Workbook

Sheet 2026-年1-12月总汇总 
A1: 月份
A2: MCC | C2: 合计 | K2: 吴含雪 | T2: 朱于森 | AC2: 梅雯慧 | AL2: 齐满艳 | AU2: 陈正深 | BD2: 齐青青 | BM2: 朱文欣 | BV2: 张耀虹 | CE2: 胡雪茜 | CN2: 蓝晨馨
A3: 币种 | C3: 美金 | F3: 人民币 | I3: 在跑广告量 | K3: 美金 | L3: 美金 | M3: 美金 | N3: 美金 | O3: 美金 | P3: 美金 | Q3: 美金 | R3: 人民币 | S3: 在跑广告量 | T3: 美金 | U3: 美金 | V3: 美金 | W3: 美金 | X3: 美金 | Y3: 美金 | Z3: 美金 | AA3: 人民币 | AB3: 在跑广告量 | AC3: 美金 | AD3: 美金 | AE3: 美金 | AF3: 美金 | AG3: 美金 | AH3: 美金 | AI3: 美金 | AJ3: 人民币 | AK3: 在跑广告量 | AL3: 美金 | AM3: 美金 | AN3: 美金 | AO3: 美金 | AP3: 美金 | AQ3: 美金 | AR3: 美金 | AS3: 人民币 | AT3: 在跑广告量 | AU3: 美金 | AV3: 美金 | AW3: 美金 | AX3: 美金 | AY3: 美金 | AZ3: 美金 | BA3: 美金 | BB3: 人民币 | BC3: 在跑广告量 | BD3: 美金 | BE3: 美金 | BF3: 美金 | BG3: 美金 | BH3: 美金 | BI3: 美金 | BJ3: 美金 | BK3: 人民币 | BL3: 在跑广告量 | BM3: 美金 | BN3: 美金 | BO3: 美金 | BP3: 美金 | BQ3: 美金 | BR3: 美金 | BS3: 美金 | BT3: 人民币 | BU3: 在跑广告量 | BV3: 美金 | BW3: 美金 | BX3: 美金 | BY3: 美金 | BZ3: 美金 | CA3: 美金 | CB3: 美金 | CC3: 人民币 | CD3: 在跑广告量 | CE3: 美金 | CF3: 美金 | CG3: 美金 | CH3: 美金 | CI3: 美金 | CJ3: 美金 | CK3: 美金 | CL3: 人民币 | CM3: 在跑广告量 | CN3: 美金 | CO3: 美金 | CP3: 美金 | CQ3: 美金 | CR3: 美金 | CS3: 美金 | CT3: 美金 | CU3: 人民币 | CV3: 在跑广告量
A4: 广告费 | C4: {=_xlfn.UNIQUE(_xlfn.VSTACK('1月份'!C4)+_xlfn.VSTACK('2月份'!C4)+_xlfn.VSTACK('3月份'!C4)+_xlfn.VSTACK('4月份'!C4)+_xlfn.VSTACK('5月份'!C4)+_xlfn.VSTACK('6月份'!C4)+_xlfn.VSTACK('7月份'!C4)+_xlfn.VSTACK('8月份'!C4)+_xlfn.VSTACK('9月份'!C4)+_xlfn.VSTACK('10月份'!C4)+_xlfn.VSTACK('11月份'!C4)+_xlfn.VSTACK('12月份'!C4))} -> 17549.52 | F4: {=_xlfn.UNIQUE(_xlfn.VSTACK('1月份'!F4)+_xlfn.VSTACK('2月份'!F4)+_xlfn.VSTACK('3月份'!F4)+_xlfn.VSTACK('4月份'!F4)+_xlfn.VSTACK('5月份'!F4)+_xlfn.VSTACK('6月份'!F4)+_xlfn.VSTACK('7月份'!F4)+_xlfn.VSTACK('8月份'!F4)+_xlfn.VSTACK('9月份'!F4)+_xlfn.VSTACK('10月份'!F4)+_xlfn.VSTACK('11月份'!F4)+_xlfn.VSTACK('12月份'!F4))} -> 19870.75 | I4: {=_xlfn.UNIQUE(_xlfn.VSTACK('1月份'!I4)+_xlfn.VSTACK('2月份'!I4)+_xlfn.VSTACK('3月份'!I4)+_xlfn.VSTACK('4月份'!I4)+_xlfn.VSTACK('5月份'!I4)+_xlfn.VSTACK('6月份'!I4)+_xlfn.VSTACK('7月份'!I4)+_xlfn.VSTACK('8月份'!I4)+_xlfn.VSTACK('9月份'!I4)+_xlfn.VSTACK('10月份'!I4)+_xlfn.VSTACK('11月份'!I4)+_xlfn.VSTACK('12月份'!I4))} -> 242 | K4: {=_xlfn.UNIQUE(_xlfn.VSTACK('1月份'!K4)+_xlfn.VSTACK('2月份'!K4)+_xlfn.VSTACK('3月份'!K4)+_xlfn.VSTACK('4月份'!K4)+_xlfn.VSTACK('5月份'!K4)+_xlfn.VSTACK('6月份'!K4)+_xlfn.VSTACK('7月份'!K4)+_xlfn.VSTACK('8月份'!K4)+_xlfn.VSTACK('9月份'!K4)+_xlfn.VSTACK('10月份'!K4)+_xlfn.VSTACK('11月份'!K4)+_xlfn.VSTACK('12月份'!K4))} -> 717.59 | L4: {=_xlfn.UNIQUE(_xlfn.VSTACK('1月份'!L4)+_xlfn.VSTACK('2月份'!L4)+_xlfn.VSTACK('3月份'!L4)+_xlfn.VSTACK('4月份'!L4)+_xlfn.VSTACK('5月份'!L4)+_xlfn.VSTACK('6月份'!L4)+_xlfn.VSTACK('7月份'!L4)+_xlfn.VSTACK('8月份'!L4)+_xlfn.VSTACK('9月份'!L4)+_xlfn.VSTACK('10月份'!L4)+_xlfn.VSTACK('11月份'!L4)+_xlfn.VSTACK('12月份'!L4))} -> 0 | M4: {=_xlfn.UNIQUE(_xlfn.VSTACK('1月份'!M4)+_xlfn.VSTACK('2月份'!M4)+_xlfn.VSTACK('3月份'!M4)+_xlfn.VSTACK('4月份'!M4)+_xlfn.VSTACK('5月份'!M4)+_xlfn.VSTACK('6月份'!M4)+_xlfn.VSTACK('7月份'!M4)+_xlfn.VSTACK('8月份'!M4)+_xlfn.VSTACK('9月份'!M4)+_xlfn.VSTACK('10月份'!M4)+_xlfn.VSTACK('11月份'!M4)+_xlfn.VSTACK('12月份'!M4))} -> 0 | N4: {=_xlfn.UNIQUE(_xlfn.VSTACK('1月份'!N4)+_xlfn.VSTACK('2月份'!N4)+_xlfn.VSTACK('3月份'!N4)+_xlfn.VSTACK('4月份'!N4)+_xlfn.VSTACK('5月份'!N4)+_xlfn.VSTACK('6月份'!N4)+_xlfn.VSTACK('7月份'!N4)+_xlfn.VSTACK('8月份'!N4)+_xlfn.VSTACK('9月份'!N4)+_xlfn.VSTACK('10月份'!N4)+_xlfn.VSTACK('11月份'!N4)+_xlfn.VSTACK('12月份'!N4))} -> 0 | O4: {=_xlfn.UNIQUE(_xlfn.VSTACK('1月份'!O4)+_xlfn.VSTACK('2月份'!O4)+_xlfn.VSTACK('3月份'!O4)+_xlfn.VSTACK('4月份'!O4)+_xlfn.VSTACK('5月份'!O4)+_xlfn.VSTACK('6月份'!O4)+_xlfn.VSTACK('7月份'!O4)+_xlfn.VSTACK('8月份'!O4)+_xlfn.VSTACK('9月份'!O4)+_xlfn.VSTACK('10月份'!O4)+_xlfn.VSTACK('11月份'!O4)+_xlfn.VSTACK('12月份'!O4))} -> 0 | P4: {=_xlfn.UNIQUE(_xlfn.VSTACK('1月份'!P4)+_xlfn.VSTACK('2月份'!P4)+_xlfn.VSTACK('3月份'!P4)+_xlfn.VSTACK('4月份'!P4)+_xlfn.VSTACK('5月份'!P4)+_xlfn.VSTACK('6月份'!P4)+_xlfn.VSTACK('7月份'!P4)+_xlfn.VSTACK('8月份'!P4)+_xlfn.VSTACK('9月份'!P4)+_xlfn.VSTACK('10月份'!P4)+_xlfn.VSTACK('11月份'!P4)+_xlfn.VSTACK('12月份'!P4))} -> 0 | Q4: {=_xlfn.UNIQUE(_xlfn.VSTACK('1月份'!Q4)+_xlfn.VSTACK('2月份'!Q4)+_xlfn.VSTACK('3月份'!Q4)+_xlfn.VSTACK('4月份'!Q4)+_xlfn.VSTACK('5月份'!Q4)+_xlfn.VSTACK('6月份'!Q4)+_xlfn.VSTACK('7月份'!Q4)+_xlfn.VSTACK('8月份'!Q4)+_xlfn.VSTACK('9月份'!Q4)+_xlfn.VSTACK('10月份'!Q4)+_xlfn.VSTACK('11月份'!Q4)+_xlfn.VSTACK('12月份'!Q4))} -> 0 | R4: {=_xlfn.UNIQUE(_xlfn.VSTACK('1月份'!R4)+_xlfn.VSTACK('2月份'!R4)+_xlfn.VSTACK('3月份'!R4)+_xlfn.VSTACK('4月份'!R4)+_xlfn.VSTACK('5月份'!R4)+_xlfn.VSTACK('6月份'!R4)+_xlfn.VSTACK('7月份'!R4)+_xlfn.VSTACK('8月份'!R4)+_xlfn.VSTACK('9月份'!R4)+_xlfn.VSTACK('10月份'!R4)+_xlfn.VSTACK('11月份'!R4)+_xlfn.VSTACK('12月份'!R4))} -> 8297.92 | ... CC4: {=_xlfn.UNIQUE(_xlfn.VSTACK('1月份'!CC4)+_xlfn.VSTACK('2月份'!CC4)+_xlfn.VSTACK('3月份'!CC4)+_xlfn.VSTACK('4月份'!CC4)+_xlfn.VSTACK('5月份'!CC4)+_xlfn.VSTACK('6月份'!CC4)+_xlfn.VSTACK('7月份'!CC4)+_xlfn.VSTACK('8月份'!CC4)+_xlfn.VSTACK('9月份'!CC4)+_xlfn.VSTACK('10月份'!CC4)+_xlfn.VSTACK('11月份'!CC4)+_xlfn.VSTACK('12月份'!CC4))} -> 0 | CD4: 9 | CE4: {=_xlfn.UNIQUE(_xlfn.VSTACK('1月份'!CE4)+_xlfn.VSTACK('2月份'!CE4)+_xlfn.VSTACK('3月份'!CE4)+_xlfn.VSTACK('4月份'!CE4)+_xlfn.VSTACK('5月份'!CE4)+_xlfn.VSTACK('6月份'!CE4)+_xlfn.VSTACK('7月份'!CE4)+_xlfn.VSTACK('8月份'!CE4)+_xlfn.VSTACK('9月份'!CE4)+_xlfn.VSTACK('10月份'!CE4)+_xlfn.VSTACK('11月份'!CE4)+_xlfn.VSTACK('12月份'!CE4))} -> 1211.95 | CF4: {=_xlfn.UNIQUE(_xlfn.VSTACK('1月份'!CF4)+_xlfn.VSTACK('2月份'!CF4)+_xlfn.VSTACK('3月份'!CF4)+_xlfn.VSTACK('4月份'!CF4)+_xlfn.VSTACK('5月份'!CF4)+_xlfn.VSTACK('6月份'!CF4)+_xlfn.VSTACK('7月份'!CF4)+_xlfn.VSTACK('8月份'!CF4)+_xlfn.VSTACK('9月份'!CF4)+_xlfn.VSTACK('10月份'!CF4)+_xlfn.VSTACK('11月份'!CF4)+_xlfn.VSTACK('12月份'!CF4))} -> 0 | CG4: {=_xlfn.UNIQUE(_xlfn.VSTACK('1月份'!CG4)+_xlfn.VSTACK('2月份'!CG4)+_xlfn.VSTACK('3月份'!CG4)+_xlfn.VSTACK('4月份'!CG4)+_xlfn.VSTACK('5月份'!CG4)+_xlfn.VSTACK('6月份'!CG4)+_xlfn.VSTACK('7月份'!CG4)+_xlfn.VSTACK('8月份'!CG4)+_xlfn.VSTACK('9月份'!CG4)+_xlfn.VSTACK('10月份'!CG4)+_xlfn.VSTACK('11月份'!CG4)+_xlfn.VSTACK('12月份'!CG4))} -> 0 | CH4: {=_xlfn.UNIQUE(_xlfn.VSTACK('1月份'!CH4)+_xlfn.VSTACK('2月份'!CH4)+_xlfn.VSTACK('3月份'!CH4)+_xlfn.VSTACK('4月份'!CH4)+_xlfn.VSTACK('5月份'!CH4)+_xlfn.VSTACK('6月份'!CH4)+_xlfn.VSTACK('7月份'!CH4)+_xlfn.VSTACK('8月份'!CH4)+_xlfn.VSTACK('9月份'!CH4)+_xlfn.VSTACK('10月份'!CH4)+_xlfn.VSTACK('11月份'!CH4)+_xlfn.VSTACK('12月份'!CH4))} -> 0 | CI4: {=_xlfn.UNIQUE(_xlfn.VSTACK('1月份'!CI4)+_xlfn.VSTACK('2月份'!CI4)+_xlfn.VSTACK('3月份'!CI4)+_xlfn.VSTACK('4月份'!CI4)+_xlfn.VSTACK('5月份'!CI4)+_xlfn.VSTACK('6月份'!CI4)+_xlfn.VSTACK('7月份'!CI4)+_xlfn.VSTACK('8月份'!CI4)+_xlfn.VSTACK('9月份'!CI4)+_xlfn.VSTACK('10月份'!CI4)+_xlfn.VSTACK('11月份'!CI4)+_xlfn.VSTACK('12月份'!CI4))} -> 0 | CJ4: {=_xlfn.UNIQUE(_xlfn.VSTACK('1月份'!CJ4)+_xlfn.VSTACK('2月份'!CJ4)+_xlfn.VSTACK('3月份'!CJ4)+_xlfn.VSTACK('4月份'!CJ4)+_xlfn.VSTACK('5月份'!CJ4)+_xlfn.VSTACK('6月份'!CJ4)+_xlfn.VSTACK('7月份'!CJ4)+_xlfn.VSTACK('8月份'!CJ4)+_xlfn.VSTACK('9月份'!CJ4)+_xlfn.VSTACK('10月份'!CJ4)+_xlfn.VSTACK('11月份'!CJ4)+_xlfn.VSTACK('12月份'!CJ4))} -> 0 | CK4: {=_xlfn.UNIQUE(_xlfn.VSTACK('1月份'!CK4)+_xlfn.VSTACK('2月份'!CK4)+_xlfn.VSTACK('3月份'!CK4)+_xlfn.VSTACK('4月份'!CK4)+_xlfn.VSTACK('5月份'!CK4)+_xlfn.VSTACK('6月份'!CK4)+_xlfn.VSTACK('7月份'!CK4)+_xlfn.VSTACK('8月份'!CK4)+_xlfn.VSTACK('9月份'!CK4)+_xlfn.VSTACK('10月份'!CK4)+_xlfn.VSTACK('11月份'!CK4)+_xlfn.VSTACK('12月份'!CK4))} -> 0 | CL4: {=_xlfn.UNIQUE(_xlfn.VSTACK('1月份'!CL4)+_xlfn.VSTACK('2月份'!CL4)+_xlfn.VSTACK('3月份'!CL4)+_xlfn.VSTACK('4月份'!CL4)+_xlfn.VSTACK('5月份'!CL4)+_xlfn.VSTACK('6月份'!CL4)+_xlfn.VSTACK('7月份'!CL4)+_xlfn.VSTACK('8月份'!CL4)+_xlfn.VSTACK('9月份'!CL4)+_xlfn.VSTACK('10月份'!CL4)+_xlfn.VSTACK('11月份'!CL4)+_xlfn.VSTACK('12月份'!CL4))} -> 0 | ... CV4: {=_xlfn.UNIQUE(_xlfn.VSTACK('1月份'!CV4)+_xlfn.VSTACK('2月份'!CV4)+_xlfn.VSTACK('3月份'!CV4)+_xlfn.VSTACK('4月份'!CV4)+_xlfn.VSTACK('5月份'!CV4)+_xlfn.VSTACK('6月份'!CV4)+_xlfn.VSTACK('7月份'!CV4)+_xlfn.VSTACK('8月份'!CV4)+_xlfn.VSTACK('9月份'!CV4)+_xlfn.VSTACK('10月份'!CV4)+_xlfn.VSTACK('11月份'!CV4)+_xlfn.VSTACK('12月份'!CV4))} -> 20
A5: 广告联盟 | C5: RW | D5: LH | E5: CG | F5: LB | G5: PM | H5: CF | I5: BSH | J5: 合计 | K5: RW | L5: LH | M5: CG | N5: LB | O5: PM | P5: CF | Q5: BSH | T5: RW | U5: LH | V5: CG | W5: LB | X5: PM | Y5: CF | Z5: BSH | AC5: RW | AD5: LH | AE5: CG | AF5: LB | AG5: PM | AH5: CF | AI5: BSH | AL5: RW | AM5: LH | AN5: CG | AO5: LB | AP5: PM | AQ5: CF | AR5: BSH | AU5: RW | AV5: LH | AW5: CG | AX5: LB | AY5: PM | AZ5: CF | BA5: BSH | BD5: RW | BE5: LH | BF5: CG | BG5: LB | BH5: PM | BI5: CF | BJ5: BSH | BM5: RW | BN5: LH | BO5: CG | BP5: LB | BQ5: PM | BR5: CF | BS5: BSH | BV5: RW | BW5: LH | BX5: CG | BY5: LB | BZ5: PM | CA5: CF | CB5: BSH | CE5: RW | CF5: LH | CG5: CG | CH5: LB | CI5: PM | CJ5: CF | CK5: BSH | CN5: RW | CO5: LH | CP5: CG | CQ5: LB | CR5: PM | CS5: CF | CT5: BSH
A6: 账号名称
A7: 账面佣金（美金） | C7: {=_xlfn.UNIQUE(_xlfn.VSTACK('1月份'!C7)+_xlfn.VSTACK('2月份'!C7)+_xlfn.VSTACK('3月份'!C7)+_xlfn.VSTACK('4月份'!C7)+_xlfn.VSTACK('5月份'!C7)+_xlfn.VSTACK('6月份'!C7)+_xlfn.VSTACK('7月份'!C7)+_xlfn.VSTACK('8月份'!C7)+_xlfn.VSTACK('9月份'!C7)+_xlfn.VSTACK('10月份'!C7)+_xlfn.VSTACK('11月份'!C7)+_xlfn.VSTACK('12月份'!C7))} -> 6096.6 | D7: {=_xlfn.UNIQUE(_xlfn.VSTACK('1月份'!D7)+_xlfn.VSTACK('2月份'!D7)+_xlfn.VSTACK('3月份'!D7)+_xlfn.VSTACK('4月份'!D7)+_xlfn.VSTACK('5月份'!D7)+_xlfn.VSTACK('6月份'!D7)+_xlfn.VSTACK('7月份'!D7)+_xlfn.VSTACK('8月份'!D7)+_xlfn.VSTACK('9月份'!D7)+_xlfn.VSTACK('10月份'!D7)+_xlfn.VSTACK('11月份'!D7)+_xlfn.VSTACK('12月份'!D7))} -> 9795.87 | E7: {=_xlfn.UNIQUE(_xlfn.VSTACK('1月份'!E7)+_xlfn.VSTACK('2月份'!E7)+_xlfn.VSTACK('3月份'!E7)+_xlfn.VSTACK('4月份'!E7)+_xlfn.VSTACK('5月份'!E7)+_xlfn.VSTACK('6月份'!E7)+_xlfn.VSTACK('7月份'!E7)+_xlfn.VSTACK('8月份'!E7)+_xlfn.VSTACK('9月份'!E7)+_xlfn.VSTACK('10月份'!E7)+_xlfn.VSTACK('11月份'!E7)+_xlfn.VSTACK('12月份'!E7))} -> 13138.82 | F7: {=_xlfn.UNIQUE(_xlfn.VSTACK('1月份'!F7)+_xlfn.VSTACK('2月份'!F7)+_xlfn.VSTACK('3月份'!F7)+_xlfn.VSTACK('4月份'!F7)+_xlfn.VSTACK('5月份'!F7)+_xlfn.VSTACK('6月份'!F7)+_xlfn.VSTACK('7月份'!F7)+_xlfn.VSTACK('8月份'!F7)+_xlfn.VSTACK('9月份'!F7)+_xlfn.VSTACK('10月份'!F7)+_xlfn.VSTACK('11月份'!F7)+_xlfn.VSTACK('12月份'!F7))} -> 9186.7 | G7: {=_xlfn.UNIQUE(_xlfn.VSTACK('1月份'!G7)+_xlfn.VSTACK('2月份'!G7)+_xlfn.VSTACK('3月份'!G7)+_xlfn.VSTACK('4月份'!G7)+_xlfn.VSTACK('5月份'!G7)+_xlfn.VSTACK('6月份'!G7)+_xlfn.VSTACK('7月份'!G7)+_xlfn.VSTACK('8月份'!G7)+_xlfn.VSTACK('9月份'!G7)+_xlfn.VSTACK('10月份'!G7)+_xlfn.VSTACK('11月份'!G7)+_xlfn.VSTACK('12月份'!G7))} -> 9827.8 | H7: {=_xlfn.UNIQUE(_xlfn.VSTACK('1月份'!H7)+_xlfn.VSTACK('2月份'!H7)+_xlfn.VSTACK('3月份'!H7)+_xlfn.VSTACK('4月份'!H7)+_xlfn.VSTACK('5月份'!H7)+_xlfn.VSTACK('6月份'!H7)+_xlfn.VSTACK('7月份'!H7)+_xlfn.VSTACK('8月份'!H7)+_xlfn.VSTACK('9月份'!H7)+_xlfn.VSTACK('10月份'!H7)+_xlfn.VSTACK('11月份'!H7)+_xlfn.VSTACK('12月份'!H7))} -> 384.02 | I7: {=_xlfn.UNIQUE(_xlfn.VSTACK('1月份'!I7)+_xlfn.VSTACK('2月份'!I7)+_xlfn.VSTACK('3月份'!I7)+_xlfn.VSTACK('4月份'!I7)+_xlfn.VSTACK('5月份'!I7)+_xlfn.VSTACK('6月份'!I7)+_xlfn.VSTACK('7月份'!I7)+_xlfn.VSTACK('8月份'!I7)+_xlfn.VSTACK('9月份'!I7)+_xlfn.VSTACK('10月份'!I7)+_xlfn.VSTACK('11月份'!I7)+_xlfn.VSTACK('12月份'!I7))} -> 167.15 | J7: {=_xlfn.UNIQUE(_xlfn.VSTACK('1月份'!J7)+_xlfn.VSTACK('2月份'!J7)+_xlfn.VSTACK('3月份'!J7)+_xlfn.VSTACK('4月份'!J7)+_xlfn.VSTACK('5月份'!J7)+_xlfn.VSTACK('6月份'!J7)+_xlfn.VSTACK('7月份'!J7)+_xlfn.VSTACK('8月份'!J7)+_xlfn.VSTACK('9月份'!J7)+_xlfn.VSTACK('10月份'!J7)+_xlfn.VSTACK('11月份'!J7)+_xlfn.VSTACK('12月份'!J7))} -> 48596.96 | ... CV7: {=_xlfn.UNIQUE(_xlfn.VSTACK('1月份'!CV7)+_xlfn.VSTACK('2月份'!CV7)+_xlfn.VSTACK('3月份'!CV7)+_xlfn.VSTACK('4月份'!CV7)+_xlfn.VSTACK('5月份'!CV7)+_xlfn.VSTACK('6月份'!CV7)+_xlfn.VSTACK('7月份'!CV7)+_xlfn.VSTACK('8月份'!CV7)+_xlfn.VSTACK('9月份'!CV7)+_xlfn.VSTACK('10月份'!CV7)+_xlfn.VSTACK('11月份'!CV7)+_xlfn.VSTACK('12月份'!CV7))} -> 0
A8: 失效佣金（美金） | C8: {=_xlfn.UNIQUE(_xlfn.VSTACK('1月份'!C8)+_xlfn.VSTACK('2月份'!C8)+_xlfn.VSTACK('3月份'!C8)+_xlfn.VSTACK('4月份'!C8)+_xlfn.VSTACK('5月份'!C8)+_xlfn.VSTACK('6月份'!C8)+_xlfn.VSTACK('7月份'!C8)+_xlfn.VSTACK('8月份'!C8)+_xlfn.VSTACK('9月份'!C8)+_xlfn.VSTACK('10月份'!C8)+_xlfn.VSTACK('11月份'!C8)+_xlfn.VSTACK('12月份'!C8))} -> 1907.24 | D8: {=_xlfn.UNIQUE(_xlfn.VSTACK('1月份'!D8)+_xlfn.VSTACK('2月份'!D8)+_xlfn.VSTACK('3月份'!D8)+_xlfn.VSTACK('4月份'!D8)+_xlfn.VSTACK('5月份'!D8)+_xlfn.VSTACK('6月份'!D8)+_xlfn.VSTACK('7月份'!D8)+_xlfn.VSTACK('8月份'!D8)+_xlfn.VSTACK('9月份'!D8)+_xlfn.VSTACK('10月份'!D8)+_xlfn.VSTACK('11月份'!D8)+_xlfn.VSTACK('12月份'!D8))} -> 2331.32 | E8: {=_xlfn.UNIQUE(_xlfn.VSTACK('1月份'!E8)+_xlfn.VSTACK('2月份'!E8)+_xlfn.VSTACK('3月份'!E8)+_xlfn.VSTACK('4月份'!E8)+_xlfn.VSTACK('5月份'!E8)+_xlfn.VSTACK('6月份'!E8)+_xlfn.VSTACK('7月份'!E8)+_xlfn.VSTACK('8月份'!E8)+_xlfn.VSTACK('9月份'!E8)+_xlfn.VSTACK('10月份'!E8)+_xlfn.VSTACK('11月份'!E8)+_xlfn.VSTACK('12月份'!E8))} -> 301.48 | F8: {=_xlfn.UNIQUE(_xlfn.VSTACK('1月份'!F8)+_xlfn.VSTACK('2月份'!F8)+_xlfn.VSTACK('3月份'!F8)+_xlfn.VSTACK('4月份'!F8)+_xlfn.VSTACK('5月份'!F8)+_xlfn.VSTACK('6月份'!F8)+_xlfn.VSTACK('7月份'!F8)+_xlfn.VSTACK('8月份'!F8)+_xlfn.VSTACK('9月份'!F8)+_xlfn.VSTACK('10月份'!F8)+_xlfn.VSTACK('11月份'!F8)+_xlfn.VSTACK('12月份'!F8))} -> 281.1 | G8: {=_xlfn.UNIQUE(_xlfn.VSTACK('1月份'!G8)+_xlfn.VSTACK('2月份'!G8)+_xlfn.VSTACK('3月份'!G8)+_xlfn.VSTACK('4月份'!G8)+_xlfn.VSTACK('5月份'!G8)+_xlfn.VSTACK('6月份'!G8)+_xlfn.VSTACK('7月份'!G8)+_xlfn.VSTACK('8月份'!G8)+_xlfn.VSTACK('9月份'!G8)+_xlfn.VSTACK('10月份'!G8)+_xlfn.VSTACK('11月份'!G8)+_xlfn.VSTACK('12月份'!G8))} -> 320.37 | H8: {=_xlfn.UNIQUE(_xlfn.VSTACK('1月份'!H8)+_xlfn.VSTACK('2月份'!H8)+_xlfn.VSTACK('3月份'!H8)+_xlfn.VSTACK('4月份'!H8)+_xlfn.VSTACK('5月份'!H8)+_xlfn.VSTACK('6月份'!H8)+_xlfn.VSTACK('7月份'!H8)+_xlfn.VSTACK('8月份'!H8)+_xlfn.VSTACK('9月份'!H8)+_xlfn.VSTACK('10月份'!H8)+_xlfn.VSTACK('11月份'!H8)+_xlfn.VSTACK('12月份'!H8))} -> 128.87 | I8: {=_xlfn.UNIQUE(_xlfn.VSTACK('1月份'!I8)+_xlfn.VSTACK('2月份'!I8)+_xlfn.VSTACK('3月份'!I8)+_xlfn.VSTACK('4月份'!I8)+_xlfn.VSTACK('5月份'!I8)+_xlfn.VSTACK('6月份'!I8)+_xlfn.VSTACK('7月份'!I8)+_xlfn.VSTACK('8月份'!I8)+_xlfn.VSTACK('9月份'!I8)+_xlfn.VSTACK('10月份'!I8)+_xlfn.VSTACK('11月份'!I8)+_xlfn.VSTACK('12月份'!I8))} -> 14.41 | J8: {=_xlfn.UNIQUE(_xlfn.VSTACK('1月份'!J8)+_xlfn.VSTACK('2月份'!J8)+_xlfn.VSTACK('3月份'!J8)+_xlfn.VSTACK('4月份'!J8)+_xlfn.VSTACK('5月份'!J8)+_xlfn.VSTACK('6月份'!J8)+_xlfn.VSTACK('7月份'!J8)+_xlfn.VSTACK('8月份'!J8)+_xlfn.VSTACK('9月份'!J8)+_xlfn.VSTACK('10月份'!J8)+_xlfn.VSTACK('11月份'!J8)+_xlfn.VSTACK('12月份'!J8))} -> 5284.79 | ... CV8: {=_xlfn.UNIQUE(_xlfn.VSTACK('1月份'!CV8)+_xlfn.VSTACK('2月份'!CV8)+_xlfn.VSTACK('3月份'!CV8)+_xlfn.VSTACK('4月份'!CV8)+_xlfn.VSTACK('5月份'!CV8)+_xlfn.VSTACK('6月份'!CV8)+_xlfn.VSTACK('7月份'!CV8)+_xlfn.VSTACK('8月份'!CV8)+_xlfn.VSTACK('9月份'!CV8)+_xlfn.VSTACK('10月份'!CV8)+_xlfn.VSTACK('11月份'!CV8)+_xlfn.VSTACK('12月份'!CV8))} -> 0
A9: 应收佣金（美金） | B9: 5号 | C9: =SUMIF($K$5:$CV$5,C$5,$K9:$CV9) -> 0 | D9: =SUMIF($K$5:$CV$5,D$5,$K9:$CV9) -> 0 | E9: =SUMIF($K$5:$CV$5,E$5,$K9:$CV9) -> 0 | F9: =SUMIF($K$5:$CV$5,F$5,$K9:$CV9) -> 0 | G9: =SUMIF($K$5:$CV$5,G$5,$K9:$CV9) -> 0 | H9: =SUMIF($K$5:$CV$5,H$5,$K9:$CV9) -> 0 | I9: =SUMIF($K$5:$CV$5,I$5,$K9:$CV9) -> 0 | J9: =SUM(C9:I9) -> 0
B10: 15号 | C10: =SUMIF($K$5:$CV$5,C$5,$K10:$CV10) -> 0 | D10: =SUMIF($K$5:$CV$5,D$5,$K10:$CV10) -> 0 | E10: =SUMIF($K$5:$CV$5,E$5,$K10:$CV10) -> 0 | F10: =SUMIF($K$5:$CV$5,F$5,$K10:$CV10) -> 0 | G10: =SUMIF($K$5:$CV$5,G$5,$K10:$CV10) -> 0 | H10: =SUMIF($K$5:$CV$5,H$5,$K10:$CV10) -> 0 | I10: =SUMIF($K$5:$CV$5,I$5,$K10:$CV10) -> 0 | J10: =SUM(C10:I10) -> 0
B11: 合计 | C11: =SUM(C9:C10) -> 0 | D11: =SUM(D9:D10) -> 0 | E11: =SUM(E9:E10) -> 0 | F11: =SUM(F9:F10) -> 0 | G11: =SUM(G9:G10) -> 0 | H11: =SUM(H9:H10) -> 0 | I11: =SUM(I9:I10) -> 0 | J11: =SUM(C11:I11) -> 0 | K11: =SUM(K9:K10) -> 0 | T11: =SUM(T9:T10) -> 0 | AC11: =SUM(AC9:AC10) -> 0 | AL11: =SUM(AL9:AL10) -> 0 | AU11: =SUM(AU9:AU10) -> 0 | BD11: =SUM(BD9:BD10) -> 0 | BM11: =SUM(BM9:BM10) -> 0 | BV11: =SUM(BV9:BV10) -> 0 | CE11: =SUM(CE9:CE10) -> 0 | CN11: =SUM(CN9:CN10) -> 0 | CU11: =SUM(CU9:CU10) -> 0
A12: 实收佣金（人民币） | B12: 10号 | C12: =SUMIF($K$5:$CV$5,C$5,$K12:$CV12) -> 0 | D12: =SUMIF($K$5:$CV$5,D$5,$K12:$CV12) -> 0 | E12: =SUMIF($K$5:$CV$5,E$5,$K12:$CV12) -> 0 | F12: =SUMIF($K$5:$CV$5,F$5,$K12:$CV12) -> 0 | G12: =SUMIF($K$5:$CV$5,G$5,$K12:$CV12) -> 0 | H12: =SUMIF($K$5:$CV$5,H$5,$K12:$CV12) -> 0 | I12: =SUMIF($K$5:$CV$5,I$5,$K12:$CV12) -> 0 | J12: =SUM(C12:I12) -> 0
B13: 20号 | C13: =SUMIF($K$5:$CV$5,C$5,$K13:$CV13) -> 0 | D13: =SUMIF($K$5:$CV$5,D$5,$K13:$CV13) -> 0 | E13: =SUMIF($K$5:$CV$5,E$5,$K13:$CV13) -> 0 | F13: =SUMIF($K$5:$CV$5,F$5,$K13:$CV13) -> 0 | G13: =SUMIF($K$5:$CV$5,G$5,$K13:$CV13) -> 0 | H13: =SUMIF($K$5:$CV$5,H$5,$K13:$CV13) -> 0 | I13: =SUMIF($K$5:$CV$5,I$5,$K13:$CV13) -> 0 | J13: =SUM(C13:I13) -> 0
B14: 合计 | C14: =SUMIF($K$3:$CU$3,C$3,$K14:$CU14) -> 0 | D14: =SUMIF($K$3:$CU$3,D$3,$K14:$CU14) -> 0 | E14: =SUMIF($K$3:$CU$3,E$3,$K14:$CU14) -> 0 | F14: =SUMIF($K$3:$CU$3,F$3,$K14:$CU14) -> 0 | G14: =SUMIF($K$3:$CU$3,G$3,$K14:$CU14) -> 0 | H14: =SUMIF($K$3:$CU$3,H$3,$K14:$CU14) -> 0 | I14: =SUMIF($K$3:$CU$3,I$3,$K14:$CU14) -> 0 | J14: =SUM(C14:I14) -> 0 | K14: =SUM(K12:K13) -> 0 | T14: =SUM(T12:T13) -> 0 | AC14: =SUM(AC12:AC13) -> 0 | AL14: =SUM(AL12:AL13) -> 0 | AU14: =SUM(AU12:AU13) -> 0 | BD14: =SUM(BD12:BD13) -> 0 | BM14: =SUM(BM12:BM13) -> 0 | BV14: =SUM(BV12:BV13) -> 0 | CE14: =SUM(CE12:CE13) -> 0 | CN14: =SUM(CN12:CN13) -> 0 | CU14: =SUM(CU12:CU13) -> 0
A15: 收款人
A16: 收款卡号
A17: 可分配利润（实收佣金-广告费） | J17: =J14-C4 -> -17549.52
J52: 吴含雪
C53: 2号朱于森龚建成交通3182 | J53: 朱于森
C54: 3号梅雯慧张文俊支付宝 | J54: 梅雯慧
C55: 3号梅雯慧龚爱珍工商0765 | J55: 齐满艳
C56: 4号齐满艳龚爱珍农业1671 | J56: 陈正深
C57: 4号齐满艳张文俊农业0089 | J57: 齐青青
C58: 5号陈正深张文俊支付宝 | J58: 朱文欣
C59: 5号陈正深张文俊建设5707 | J59: 张耀红
C60: 6号齐青青龚建成中信6613 | J60: 胡雪茜
C61: 6号齐青青张文俊工商5542 | J61: 蓝晨馨
C62: 7号朱文欣龚建成交通3183
C63: 7号朱文欣龚建成建设数2576
C64: 8号张耀红张文俊广发8727
C65: 8号张耀红张文俊建设数2659
C66: 9号胡雪茜龚建成广发1786
C67: 9号胡雪茜龚建成工商3179
C68: 9号胡雪茜龚建成工商3306
C69: 10号蓝晨馨龚建成中信4298
C70: 10号蓝晨馨张文雅建行3055

Sheet 1月份
A1: 月份
A2: MCC | C2: 合计 | K2: 吴含雪 | T2: 朱于森 | AC2: 梅雯慧 | AL2: 齐满艳 | AU2: 陈正深 | BD2: 齐青青 | BM2: 朱文欣 | BV2: 张耀虹 | CE2: 胡雪茜 | CN2: 蓝晨馨
A3: 币种 | C3: 美金 | F3: 人民币 | I3: 在跑广告量 | K3: 美金 | L3: 美金 | M3: 美金 | N3: 美金 | O3: 美金 | P3: 美金 | Q3: 美金 | R3: 人民币 | S3: 在跑广告量 | T3: 美金 | U3: 美金 | V3: 美金 | W3: 美金 | X3: 美金 | Y3: 美金 | Z3: 美金 | AA3: 人民币 | AB3: 在跑广告量 | AC3: 美金 | AD3: 美金 | AE3: 美金 | AF3: 美金 | AG3: 美金 | AH3: 美金 | AI3: 美金 | AJ3: 人民币 | AK3: 在跑广告量 | AL3: 美金 | AM3: 美金 | AN3: 美金 | AO3: 美金 | AP3: 美金 | AQ3: 美金 | AR3: 美金 | AS3: 人民币 | AT3: 在跑广告量 | AU3: 美金 | AV3: 美金 | AW3: 美金 | AX3: 美金 | AY3: 美金 | AZ3: 美金 | BA3: 美金 | BB3: 人民币 | BC3: 在跑广告量 | BD3: 美金 | BE3: 美金 | BF3: 美金 | BG3: 美金 | BH3: 美金 | BI3: 美金 | BJ3: 美金 | BK3: 人民币 | BL3: 在跑广告量 | BM3: 美金 | BN3: 美金 | BO3: 美金 | BP3: 美金 | BQ3: 美金 | BR3: 美金 | BS3: 美金 | BT3: 人民币 | BU3: 在跑广告量 | BV3: 美金 | BW3: 美金 | BX3: 美金 | BY3: 美金 | BZ3: 美金 | CA3: 美金 | CB3: 美金 | CC3: 人民币 | CD3: 在跑广告量 | CE3: 美金 | CF3: 美金 | CG3: 美金 | CH3: 美金 | CI3: 美金 | CJ3: 美金 | CK3: 美金 | CL3: 人民币 | CM3: 在跑广告量 | CN3: 美金 | CO3: 美金 | CP3: 美金 | CQ3: 美金 | CR3: 美金 | CS3: 美金 | CT3: 美金 | CU3: 人民币 | CV3: 在跑广告量
A4: 广告费 | C4: =SUMIF($K$3:$CV$3,C$3,$K4:$CV4) -> 17549.52 | F4: =SUMIF($K$3:$CV$3,F$3,$K4:$CV4) -> 19870.75 | I4: =SUMIF($K$3:$CV$3,I$3,$K4:$CV4) -> 242 | K4: 717.59 | R4: 8297.92 | S4: 25 | T4: 2835.38 | AB4: 23 | AC4: 638.69 | AJ4: 2905.83 | AK4: 28 | AL4: 3410 | AT4: 17 | AU4: 2217 | BB4: 8667 | BC4: 31 | BD4: 1637.75 | BL4: 30 | BM4: 372.17 | BN4: 1466.3 | BU4: 4 | BV4: 1227.69 | CD4: 38 | CE4: 1211.95 | CM4: 26 | CN4: 1815 | CV4: 20
A5: 广告联盟 | C5: RW | D5: LH | E5: CG | F5: LB | G5: PM | H5: CF | I5: BSH | J5: 合计 | K5: RW | L5: LH | M5: CG | N5: LB | O5: PM | P5: CF | Q5: BSH | T5: RW | U5: LH | V5: CG | W5: LB | X5: PM | Y5: CF | Z5: BSH | AC5: RW | AD5: LH | AE5: CG | AF5: LB | AG5: PM | AH5: CF | AI5: BSH | AL5: RW | AM5: LH | AN5: CG | AO5: LB | AP5: PM | AQ5: CF | AR5: BSH | AU5: RW | AV5: LH | AW5: CG | AX5: LB | AY5: PM | AZ5: CF | BA5: BSH | BD5: RW | BE5: LH | BF5: CG | BG5: LB | BH5: PM | BI5: CF | BJ5: BSH | BM5: RW | BN5: LH | BO5: CG | BP5: LB | BQ5: PM | BR5: CF | BS5: BSH | BV5: RW | BW5: LH | BX5: CG | BY5: LB | BZ5: PM | CA5: CF | CB5: BSH | CE5: RW | CF5: LH | CG5: CG | CH5: LB | CI5: PM | CJ5: CF | CK5: BSH | CN5: RW | CO5: LH | CP5: CG | CQ5: LB | CR5: PM | CS5: CF | CT5: BSH
A6: 账号名称 | M6: weili | N6: tuancha | Q6: bloomroots | U6: wenjun1 | V6: wenjun3 | AC6: wenjun03 | AD6: tuancha | AE6: novanest | AH6: allurahub | AL6: wenjun | AP6: weilixia | AU6: everydayhaven | AV6: kagetsu | AY6: vitahaven | BD6: kaizenflowshop | BF6: wenjun2 | BI6: everydayhaven | BN6: wenjun3 | BO6: vitahaven | BW6: wenjun2 | BZ6: tuancha | CA6: bloomroots | CG6: everydayhaven | CH6: weilixia | CN6: RW1 thgoodsandguard | CO6: LH allurahub | CP6: CG1bloomroots
A7: 账面佣金（美金） | C7: =SUMIF($K$5:$CV$5,C$5,$K7:$CV7) -> 6096.6 | D7: =SUMIF($K$5:$CV$5,D$5,$K7:$CV7) -> 9795.87 | E7: =SUMIF($K$5:$CV$5,E$5,$K7:$CV7) -> 13138.82 | F7: =SUMIF($K$5:$CV$5,F$5,$K7:$CV7) -> 9186.7 | G7: =SUMIF($K$5:$CV$5,G$5,$K7:$CV7) -> 9827.8 | H7: =SUMIF($K$5:$CV$5,H$5,$K7:$CV7) -> 384.02 | I7: =SUMIF($K$5:$CV$5,I$5,$K7:$CV7) -> 167.15 | J7: =SUM(C7:I7) -> 48596.96 | M7: 3446.04 | N7: 466.11 | Q7: 167.15 | U7: 2029.23 | V7: 3554.46 | AC7: 153.88 | AD7: 1717.92 | AE7: 85.02 | AH7: 87.58 | AL7: 689 | AP7: 6945.96 | AU7: 984.55 | AV7: 4881.99 | AY7: 155.52 | BD7: 840.32 | BF7: 2919.4 | BI7: 218.45 | BM7: 1964.94 | BN7: 307.15 | BO7: 420.24 | BW7: 815.34 | BZ7: 2726.32 | CA7: 77.99 | CG7: 1119.58 | CH7: 8720.59 | CN7: 1463.91 | CO7: 44.24 | CP7: 1594.08
A8: 失效佣金（美金） | C8: =SUMIF($K$5:$CV$5,C$5,$K8:$CV8) -> 1907.24 | D8: =SUMIF($K$5:$CV$5,D$5,$K8:$CV8) -> 2331.32 | E8: =SUMIF($K$5:$CV$5,E$5,$K8:$CV8) -> 301.48 | F8: =SUMIF($K$5:$CV$5,F$5,$K8:$CV8) -> 281.1 | G8: =SUMIF($K$5:$CV$5,G$5,$K8:$CV8) -> 320.37 | H8: =SUMIF($K$5:$CV$5,H$5,$K8:$CV8) -> 128.87 | I8: =SUMIF($K$5:$CV$5,I$5,$K8:$CV8) -> 14.41 | J8: =SUM(C8:I8) -> 5284.79 | M8: 51.86 | N8: 3.37 | Q8: 14.41 | U8: 570 | V8: 62.45 | AC8: 2.5 | AD8: 307.41 | AH8: 31.38 | AL8: 69 | AP8: 229.1 | AU8: 978.96 | AV8: 1027.53 | BD8: 45.24 | BF8: 70.44 | BI8: 97.49 | BM8: 443.7 | BN8: 104.72 | BO8: 4.48 | BW8: 321.66 | BZ8: 91.27 | CA8: 0 | CG8: 106.5 | CH8: 277.73 | CN8: 367.84 | CP8: 5.75
A9: 应收佣金（美金） | B9: 5号 | C9: =SUMIF($K$5:$CV$5,C$5,$K9:$CV9) -> 0 | D9: =SUMIF($K$5:$CV$5,D$5,$K9:$CV9) -> 0 | E9: =SUMIF($K$5:$CV$5,E$5,$K9:$CV9) -> 0 | F9: =SUMIF($K$5:$CV$5,F$5,$K9:$CV9) -> 0 | G9: =SUMIF($K$5:$CV$5,G$5,$K9:$CV9) -> 0 | H9: =SUMIF($K$5:$CV$5,H$5,$K9:$CV9) -> 0 | I9: =SUMIF($K$5:$CV$5,I$5,$K9:$CV9) -> 0 | J9: =SUM(C9:I9) -> 0
B10: 15号 | C10: =SUMIF($K$5:$CV$5,C$5,$K10:$CV10) -> 0 | D10: =SUMIF($K$5:$CV$5,D$5,$K10:$CV10) -> 0 | E10: =SUMIF($K$5:$CV$5,E$5,$K10:$CV10) -> 0 | F10: =SUMIF($K$5:$CV$5,F$5,$K10:$CV10) -> 0 | G10: =SUMIF($K$5:$CV$5,G$5,$K10:$CV10) -> 0 | H10: =SUMIF($K$5:$CV$5,H$5,$K10:$CV10) -> 0 | I10: =SUMIF($K$5:$CV$5,I$5,$K10:$CV10) -> 0 | J10: =SUM(C10:I10) -> 0
B11: 合计 | C11: =SUM(C9:C10) -> 0 | D11: =SUM(D9:D10) -> 0 | E11: =SUM(E9:E10) -> 0 | F11: =SUM(F9:F10) -> 0 | G11: =SUM(G9:G10) -> 0 | H11: =SUM(H9:H10) -> 0 | I11: =SUM(I9:I10) -> 0 | J11: =SUM(C11:I11) -> 0 | K11: =SUM(K9:K10) -> 0 | T11: =SUM(T9:T10) -> 0 | AC11: =SUM(AC9:AC10) -> 0 | AL11: =SUM(AL9:AL10) -> 0 | AU11: =SUM(AU9:AU10) -> 0 | BD11: =SUM(BD9:BD10) -> 0 | BM11: =SUM(BM9:BM10) -> 0 | BV11: =SUM(BV9:BV10) -> 0 | CE11: =SUM(CE9:CE10) -> 0 | CN11: =SUM(CN9:CN10) -> 0 | CU11: =SUM(CU9:CU10) -> 0
A12: 实收佣金（人民币） | B12: 10号 | C12: =SUMIF($K$5:$CV$5,C$5,$K12:$CV12) -> 0 | D12: =SUMIF($K$5:$CV$5,D$5,$K12:$CV12) -> 0 | E12: =SUMIF($K$5:$CV$5,E$5,$K12:$CV12) -> 0 | F12: =SUMIF($K$5:$CV$5,F$5,$K12:$CV12) -> 0 | G12: =SUMIF($K$5:$CV$5,G$5,$K12:$CV12) -> 0 | H12: =SUMIF($K$5:$CV$5,H$5,$K12:$CV12) -> 0 | I12: =SUMIF($K$5:$CV$5,I$5,$K12:$CV12) -> 0 | J12: =SUM(C12:I12) -> 0
B13: 20号 | C13: =SUMIF($K$5:$CV$5,C$5,$K13:$CV13) -> 0 | D13: =SUMIF($K$5:$CV$5,D$5,$K13:$CV13) -> 0 | E13: =SUMIF($K$5:$CV$5,E$5,$K13:$CV13) -> 0 | F13: =SUMIF($K$5:$CV$5,F$5,$K13:$CV13) -> 0 | G13: =SUMIF($K$5:$CV$5,G$5,$K13:$CV13) -> 0 | H13: =SUMIF($K$5:$CV$5,H$5,$K13:$CV13) -> 0 | I13: =SUMIF($K$5:$CV$5,I$5,$K13:$CV13) -> 0 | J13: =SUM(C13:I13) -> 0
B14: 合计 | C14: =SUMIF($K$3:$CU$3,C$3,$K14:$CU14) -> 0 | D14: =SUMIF($K$3:$CU$3,D$3,$K14:$CU14) -> 0 | E14: =SUMIF($K$3:$CU$3,E$3,$K14:$CU14) -> 0 | F14: =SUMIF($K$3:$CU$3,F$3,$K14:$CU14) -> 0 | G14: =SUMIF($K$3:$CU$3,G$3,$K14:$CU14) -> 0 | H14: =SUMIF($K$3:$CU$3,H$3,$K14:$CU14) -> 0 | I14: =SUMIF($K$3:$CU$3,I$3,$K14:$CU14) -> 0 | J14: =SUM(C14:I14) -> 0 | K14: =SUM(K12:K13) -> 0 | T14: =SUM(T12:T13) -> 0 | AC14: =SUM(AC12:AC13) -> 0 | AL14: =SUM(AL12:AL13) -> 0 | AU14: =SUM(AU12:AU13) -> 0 | BD14: =SUM(BD12:BD13) -> 0 | BM14: =SUM(BM12:BM13) -> 0 | BV14: =SUM(BV12:BV13) -> 0 | CE14: =SUM(CE12:CE13) -> 0 | CN14: =SUM(CN12:CN13) -> 0 | CU14: =SUM(CU12:CU13) -> 0
A15: 收款人
A16: 收款卡号
A17: 可分配利润（实收佣金-广告费） | J17: =J14-C4 -> -17549.52
J52: 吴含雪
C53: 2号朱于森龚建成交通3182 | J53: 朱于森
C54: 3号梅雯慧张文俊支付宝 | J54: 梅雯慧
C55: 3号梅雯慧龚爱珍工商0765 | J55: 齐满艳
C56: 4号齐满艳龚爱珍农业1671 | J56: 陈正深
C57: 4号齐满艳张文俊农业0089 | J57: 齐青青
C58: 5号陈正深张文俊支付宝 | J58: 朱文欣
C59: 5号陈正深张文俊建设5707 | J59: 张耀红
C60: 6号齐青青龚建成中信6613 | J60: 胡雪茜
C61: 6号齐青青张文俊工商5542 | J61: 蓝晨馨
C62: 7号朱文欣龚建成交通3183
C63: 7号朱文欣龚建成建设数2576
C64: 8号张耀红张文俊广发8727
C65: 8号张耀红张文俊建设数2659
C66: 9号胡雪茜龚建成广发1786
C67: 9号胡雪茜龚建成工商3179
C68: 9号胡雪茜龚建成工商3306
C69: 10号蓝晨馨龚建成中信4298
C70: 10号蓝晨馨张文雅建行3055

Sheet 2月份
A1: 月份
A2: MCC | C2: 合计 | K2: 吴含雪 | T2: 朱于森 | AC2: 梅雯慧 | AL2: 齐满艳 | AU2: 陈正深 | BD2: 齐青青 | BM2: 朱文欣 | BV2: 张耀虹 | CE2: 胡雪茜 | CN2: 蓝晨馨
A3: 币种 | C3: 美金 | F3: 人民币 | I3: 在跑广告量 | K3: 美金 | L3: 美金 | M3: 美金 | N3: 美金 | O3: 美金 | P3: 美金 | Q3: 美金 | R3: 人民币 | S3: 在跑广告量 | T3: 美金 | U3: 美金 | V3: 美金 | W3: 美金 | X3: 美金 | Y3: 美金 | Z3: 美金 | AA3: 人民币 | AB3: 在跑广告量 | AC3: 美金 | AD3: 美金 | AE3: 美金 | AF3: 美金 | AG3: 美金 | AH3: 美金 | AI3: 美金 | AJ3: 人民币 | AK3: 在跑广告量 | AL3: 美金 | AM3: 美金 | AN3: 美金 | AO3: 美金 | AP3: 美金 | AQ3: 美金 | AR3: 美金 | AS3: 人民币 | AT3: 在跑广告量 | AU3: 美金 | AV3: 美金 | AW3: 美金 | AX3: 美金 | AY3: 美金 | AZ3: 美金 | BA3: 美金 | BB3: 人民币 | BC3: 在跑广告量 | BD3: 美金 | BE3: 美金 | BF3: 美金 | BG3: 美金 | BH3: 美金 | BI3: 美金 | BJ3: 美金 | BK3: 人民币 | BL3: 在跑广告量 | BM3: 美金 | BN3: 美金 | BO3: 美金 | BP3: 美金 | BQ3: 美金 | BR3: 美金 | BS3: 美金 | BT3: 人民币 | BU3: 在跑广告量 | BV3: 美金 | BW3: 美金 | BX3: 美金 | BY3: 美金 | BZ3: 美金 | CA3: 美金 | CB3: 美金 | CC3: 人民币 | CD3: 在跑广告量 | CE3: 美金 | CF3: 美金 | CG3: 美金 | CH3: 美金 | CI3: 美金 | CJ3: 美金 | CK3: 美金 | CL3: 人民币 | CM3: 在跑广告量 | CN3: 美金 | CO3: 美金 | CP3: 美金 | CQ3: 美金 | CR3: 美金 | CS3: 美金 | CT3: 美金 | CU3: 人民币 | CV3: 在跑广告量
A4: 广告费
A5: 广告联盟 | C5: RW | D5: LH | E5: CG | F5: LB | G5: PM | H5: CF | I5: BSH | J5: 合计 | K5: RW | L5: LH | M5: CG | N5: LB | O5: PM | P5: CF | Q5: BSH | T5: RW | U5: LH | V5: CG | W5: LB | X5: PM | Y5: CF | Z5: BSH | AC5: RW | AD5: LH | AE5: CG | AF5: LB | AG5: PM | AH5: CF | AI5: BSH | AL5: RW | AM5: LH | AN5: CG | AO5: LB | AP5: PM | AQ5: CF | AR5: BSH | AU5: RW | AV5: LH | AW5: CG | AX5: LB | AY5: PM | AZ5: CF | BA5: BSH | BD5: RW | BE5: LH | BF5: CG | BG5: LB | BH5: PM | BI5: CF | BJ5: BSH | BM5: RW | BN5: LH | BO5: CG | BP5: LB | BQ5: PM | BR5: CF | BS5: BSH | BV5: RW | BW5: LH | BX5: CG | BY5: LB | BZ5: PM | CA5: CF | CB5: BSH | CE5: RW | CF5: LH | CG5: CG | CH5: LB | CI5: PM | CJ5: CF | CK5: BSH | CN5: RW | CO5: LH | CP5: CG | CQ5: LB | CR5: PM | CS5: CF | CT5: BSH
A6: 账号名称
A7: 账面佣金（美金） | C7: =SUMIF($K$5:$CV$5,C$5,$K7:$CV7) -> 0 | D7: =SUMIF($K$5:$CV$5,D$5,$K7:$CV7) -> 0 | E7: =SUMIF($K$5:$CV$5,E$5,$K7:$CV7) -> 0 | F7: =SUMIF($K$5:$CV$5,F$5,$K7:$CV7) -> 0 | G7: =SUMIF($K$5:$CV$5,G$5,$K7:$CV7) -> 0 | H7: =SUMIF($K$5:$CV$5,H$5,$K7:$CV7) -> 0 | I7: =SUMIF($K$5:$CV$5,I$5,$K7:$CV7) -> 0
A8: 失效佣金（美金） | C8: =SUMIF($K$5:$CV$5,C$5,$K8:$CV8) -> 0 | D8: =SUMIF($K$5:$CV$5,D$5,$K8:$CV8) -> 0 | E8: =SUMIF($K$5:$CV$5,E$5,$K8:$CV8) -> 0 | F8: =SUMIF($K$5:$CV$5,F$5,$K8:$CV8) -> 0 | G8: =SUMIF($K$5:$CV$5,G$5,$K8:$CV8) -> 0 | H8: =SUMIF($K$5:$CV$5,H$5,$K8:$CV8) -> 0 | I8: =SUMIF($K$5:$CV$5,I$5,$K8:$CV8) -> 0
A9: 应收佣金（美金） | B9: 5号 | C9: =SUMIF($K$5:$CV$5,C$5,$K9:$CV9) -> 0 | D9: =SUMIF($K$5:$CV$5,D$5,$K9:$CV9) -> 0 | E9: =SUMIF($K$5:$CV$5,E$5,$K9:$CV9) -> 0 | F9: =SUMIF($K$5:$CV$5,F$5,$K9:$CV9) -> 0 | G9: =SUMIF($K$5:$CV$5,G$5,$K9:$CV9) -> 0 | H9: =SUMIF($K$5:$CV$5,H$5,$K9:$CV9) -> 0 | I9: =SUMIF($K$5:$CV$5,I$5,$K9:$CV9) -> 0 | J9: =SUM(C9:I9) -> 0
B10: 15号 | C10: =SUMIF($K$5:$CV$5,C$5,$K10:$CV10) -> 0 | D10: =SUMIF($K$5:$CV$5,D$5,$K10:$CV10) -> 0 | E10: =SUMIF($K$5:$CV$5,E$5,$K10:$CV10) -> 0 | F10: =SUMIF($K$5:$CV$5,F$5,$K10:$CV10) -> 0 | G10: =SUMIF($K$5:$CV$5,G$5,$K10:$CV10) -> 0 | H10: =SUMIF($K$5:$CV$5,H$5,$K10:$CV10) -> 0 | I10: =SUMIF($K$5:$CV$5,I$5,$K10:$CV10) -> 0 | J10: =SUM(C10:I10) -> 0
B11: 合计 | C11: =SUM(C9:C10) -> 0 | D11: =SUM(D9:D10) -> 0 | E11: =SUM(E9:E10) -> 0 | F11: =SUM(F9:F10) -> 0 | G11: =SUM(G9:G10) -> 0 | H11: =SUM(H9:H10) -> 0 | I11: =SUM(I9:I10) -> 0 | J11: =SUM(C11:I11) -> 0 | K11: =SUM(K9:K10) -> 0 | T11: =SUM(T9:T10) -> 0 | AC11: =SUM(AC9:AC10) -> 0 | AL11: =SUM(AL9:AL10) -> 0 | AU11: =SUM(AU9:AU10) -> 0 | BD11: =SUM(BD9:BD10) -> 0 | BM11: =SUM(BM9:BM10) -> 0 | BV11: =SUM(BV9:BV10) -> 0 | CE11: =SUM(CE9:CE10) -> 0 | CN11: =SUM(CN9:CN10) -> 0 | CU11: =SUM(CU9:CU10) -> 0
A12: 实收佣金（人民币） | B12: 10号 | C12: =SUMIF($K$5:$CV$5,C$5,$K12:$CV12) -> 0 | D12: =SUMIF($K$5:$CV$5,D$5,$K12:$CV12) -> 0 | E12: =SUMIF($K$5:$CV$5,E$5,$K12:$CV12) -> 0 | F12: =SUMIF($K$5:$CV$5,F$5,$K12:$CV12) -> 0 | G12: =SUMIF($K$5:$CV$5,G$5,$K12:$CV12) -> 0 | H12: =SUMIF($K$5:$CV$5,H$5,$K12:$CV12) -> 0 | I12: =SUMIF($K$5:$CV$5,I$5,$K12:$CV12) -> 0 | J12: =SUM(C12:I12) -> 0
B13: 20号 | C13: =SUMIF($K$5:$CV$5,C$5,$K13:$CV13) -> 0 | D13: =SUMIF($K$5:$CV$5,D$5,$K13:$CV13) -> 0 | E13: =SUMIF($K$5:$CV$5,E$5,$K13:$CV13) -> 0 | F13: =SUMIF($K$5:$CV$5,F$5,$K13:$CV13) -> 0 | G13: =SUMIF($K$5:$CV$5,G$5,$K13:$CV13) -> 0 | H13: =SUMIF($K$5:$CV$5,H$5,$K13:$CV13) -> 0 | I13: =SUMIF($K$5:$CV$5,I$5,$K13:$CV13) -> 0 | J13: =SUM(C13:I13) -> 0
B14: 合计 | C14: =SUMIF($K$3:$CU$3,C$3,$K14:$CU14) -> 0 | D14: =SUMIF($K$3:$CU$3,D$3,$K14:$CU14) -> 0 | E14: =SUMIF($K$3:$CU$3,E$3,$K14:$CU14) -> 0 | F14: =SUMIF($K$3:$CU$3,F$3,$K14:$CU14) -> 0 | G14: =SUMIF($K$3:$CU$3,G$3,$K14:$CU14) -> 0 | H14: =SUMIF($K$3:$CU$3,H$3,$K14:$CU14) -> 0 | I14: =SUMIF($K$3:$CU$3,I$3,$K14:$CU14) -> 0 | J14: =SUM(C14:I14) -> 0 | K14: =SUM(K12:K13) -> 0 | T14: =SUM(T12:T13) -> 0 | AC14: =SUM(AC12:AC13) -> 0 | AL14: =SUM(AL12:AL13) -> 0 | AU14: =SUM(AU12:AU13) -> 0 | BD14: =SUM(BD12:BD13) -> 0 | BM14: =SUM(BM12:BM13) -> 0 | BV14: =SUM(BV12:BV13) -> 0 | CE14: =SUM(CE12:CE13) -> 0 | CN14: =SUM(CN12:CN13) -> 0 | CU14: =SUM(CU12:CU13) -> 0
A15: 收款人
A16: 收款卡号
A17: 可分配利润（实收佣金-广告费） | J17: =J14-C4 -> 0
J52: 吴含雪
C53: 2号朱于森龚建成交通3182 | J53: 朱于森
C54: 3号梅雯慧张文俊支付宝 | J54: 梅雯慧
C55: 3号梅雯慧龚爱珍工商0765 | J55: 齐满艳
C56: 4号齐满艳龚爱珍农业1671 | J56: 陈正深
C57: 4号齐满艳张文俊农业0089 | J57: 齐青青
C58: 5号陈正深张文俊支付宝 | J58: 朱文欣
C59: 5号陈正深张文俊建设5707 | J59: 张耀红
C60: 6号齐青青龚建成中信6613 | J60: 胡雪茜
C61: 6号齐青青张文俊工商5542 | J61: 蓝晨馨
C62: 7号朱文欣龚建成交通3183
C63: 7号朱文欣龚建成建设数2576
C64: 8号张耀红张文俊广发8727
C65: 8号张耀红张文俊建设数2659
C66: 9号胡雪茜龚建成广发1786
C67: 9号胡雪茜龚建成工商3179
C68: 9号胡雪茜龚建成工商3306
C69: 10号蓝晨馨龚建成中信4298
C70: 10号蓝晨馨张文雅建行3055

Sheet 3月份
A1: 月份
A2: MCC | C2: 合计 | K2: 吴含雪 | T2: 朱于森 | AC2: 梅雯慧 | AL2: 齐满艳 | AU2: 陈正深 | BD2: 齐青青 | BM2: 朱文欣 | BV2: 张耀虹 | CE2: 胡雪茜 | CN2: 蓝晨馨
A3: 币种 | C3: 美金 | F3: 人民币 | I3: 在跑广告量 | K3: 美金 | L3: 美金 | M3: 美金 | N3: 美金 | O3: 美金 | P3: 美金 | Q3: 美金 | R3: 人民币 | S3: 在跑广告量 | T3: 美金 | U3: 美金 | V3: 美金 | W3: 美金 | X3: 美金 | Y3: 美金 | Z3: 美金 | AA3: 人民币 | AB3: 在跑广告量 | AC3: 美金 | AD3: 美金 | AE3: 美金 | AF3: 美金 | AG3: 美金 | AH3: 美金 | AI3: 美金 | AJ3: 人民币 | AK3: 在跑广告量 | AL3: 美金 | AM3: 美金 | AN3: 美金 | AO3: 美金 | AP3: 美金 | AQ3: 美金 | AR3: 美金 | AS3: 人民币 | AT3: 在跑广告量 | AU3: 美金 | AV3: 美金 | AW3: 美金 | AX3: 美金 | AY3: 美金 | AZ3: 美金 | BA3: 美金 | BB3: 人民币 | BC3: 在跑广告量 | BD3: 美金 | BE3: 美金 | BF3: 美金 | BG3: 美金 | BH3: 美金 | BI3: 美金 | BJ3: 美金 | BK3: 人民币 | BL3: 在跑广告量 | BM3: 美金 | BN3: 美金 | BO3: 美金 | BP3: 美金 | BQ3: 美金 | BR3: 美金 | BS3: 美金 | BT3: 人民币 | BU3: 在跑广告量 | BV3: 美金 | BW3: 美金 | BX3: 美金 | BY3: 美金 | BZ3: 美金 | CA3: 美金 | CB3: 美金 | CC3: 人民币 | CD3: 在跑广告量 | CE3: 美金 | CF3: 美金 | CG3: 美金 | CH3: 美金 | CI3: 美金 | CJ3: 美金 | CK3: 美金 | CL3: 人民币 | CM3: 在跑广告量 | CN3: 美金 | CO3: 美金 | CP3: 美金 | CQ3: 美金 | CR3: 美金 | CS3: 美金 | CT3: 美金 | CU3: 人民币 | CV3: 在跑广告量
A4: 广告费 | F4: =SUMIF($K$3:$CV$3,F$3,$K4:$CV4) -> 0
A5: 广告联盟 | C5: RW | D5: LH | E5: CG | F5: LB | G5: PM | H5: CF | I5: BSH | J5: 合计 | K5: RW | L5: LH | M5: CG | N5: LB | O5: PM | P5: CF | Q5: BSH | T5: RW | U5: LH | V5: CG | W5: LB | X5: PM | Y5: CF | Z5: BSH | AC5: RW | AD5: LH | AE5: CG | AF5: LB | AG5: PM | AH5: CF | AI5: BSH | AL5: RW | AM5: LH | AN5: CG | AO5: LB | AP5: PM | AQ5: CF | AR5: BSH | AU5: RW | AV5: LH | AW5: CG | AX5: LB | AY5: PM | AZ5: CF | BA5: BSH | BD5: RW | BE5: LH | BF5: CG | BG5: LB | BH5: PM | BI5: CF | BJ5: BSH | BM5: RW | BN5: LH | BO5: CG | BP5: LB | BQ5: PM | BR5: CF | BS5: BSH | BV5: RW | BW5: LH | BX5: CG | BY5: LB | BZ5: PM | CA5: CF | CB5: BSH | CE5: RW | CF5: LH | CG5: CG | CH5: LB | CI5: PM | CJ5: CF | CK5: BSH | CN5: RW | CO5: LH | CP5: CG | CQ5: LB | CR5: PM | CS5: CF | CT5: BSH
A6: 账号名称
A7: 账面佣金（美金）
A8: 失效佣金（美金）
A9: 应收佣金（美金） | B9: 5号 | C9: =SUMIF($K$5:$CV$5,C$5,$K9:$CV9) -> 0 | D9: =SUMIF($K$5:$CV$5,D$5,$K9:$CV9) -> 0 | E9: =SUMIF($K$5:$CV$5,E$5,$K9:$CV9) -> 0 | F9: =SUMIF($K$5:$CV$5,F$5,$K9:$CV9) -> 0 | G9: =SUMIF($K$5:$CV$5,G$5,$K9:$CV9) -> 0 | H9: =SUMIF($K$5:$CV$5,H$5,$K9:$CV9) -> 0 | I9: =SUMIF($K$5:$CV$5,I$5,$K9:$CV9) -> 0 | J9: =SUM(C9:I9) -> 0
B10: 15号 | C10: =SUMIF($K$5:$CV$5,C$5,$K10:$CV10) -> 0 | D10: =SUMIF($K$5:$CV$5,D$5,$K10:$CV10) -> 0 | E10: =SUMIF($K$5:$CV$5,E$5,$K10:$CV10) -> 0 | F10: =SUMIF($K$5:$CV$5,F$5,$K10:$CV10) -> 0 | G10: =SUMIF($K$5:$CV$5,G$5,$K10:$CV10) -> 0 | H10: =SUMIF($K$5:$CV$5,H$5,$K10:$CV10) -> 0 | I10: =SUMIF($K$5:$CV$5,I$5,$K10:$CV10) -> 0 | J10: =SUM(C10:I10) -> 0
B11: 合计 | C11: =SUM(C9:C10) -> 0 | D11: =SUM(D9:D10) -> 0 | E11: =SUM(E9:E10) -> 0 | F11: =SUM(F9:F10) -> 0 | G11: =SUM(G9:G10) -> 0 | H11: =SUM(H9:H10) -> 0 | I11: =SUM(I9:I10) -> 0 | J11: =SUM(C11:I11) -> 0 | K11: =SUM(K9:K10) -> 0 | T11: =SUM(T9:T10) -> 0 | AC11: =SUM(AC9:AC10) -> 0 | AL11: =SUM(AL9:AL10) -> 0 | AU11: =SUM(AU9:AU10) -> 0 | BD11: =SUM(BD9:BD10) -> 0 | BM11: =SUM(BM9:BM10) -> 0 | BV11: =SUM(BV9:BV10) -> 0 | CE11: =SUM(CE9:CE10) -> 0 | CN11: =SUM(CN9:CN10) -> 0 | CU11: =SUM(CU9:CU10) -> 0
A12: 实收佣金（人民币） | B12: 10号 | C12: =SUMIF($K$5:$CV$5,C$5,$K12:$CV12) -> 0 | D12: =SUMIF($K$5:$CV$5,D$5,$K12:$CV12) -> 0 | E12: =SUMIF($K$5:$CV$5,E$5,$K12:$CV12) -> 0 | F12: =SUMIF($K$5:$CV$5,F$5,$K12:$CV12) -> 0 | G12: =SUMIF($K$5:$CV$5,G$5,$K12:$CV12) -> 0 | H12: =SUMIF($K$5:$CV$5,H$5,$K12:$CV12) -> 0 | I12: =SUMIF($K$5:$CV$5,I$5,$K12:$CV12) -> 0 | J12: =SUM(C12:I12) -> 0
B13: 20号 | C13: =SUMIF($K$5:$CV$5,C$5,$K13:$CV13) -> 0 | D13: =SUMIF($K$5:$CV$5,D$5,$K13:$CV13) -> 0 | E13: =SUMIF($K$5:$CV$5,E$5,$K13:$CV13) -> 0 | F13: =SUMIF($K$5:$CV$5,F$5,$K13:$CV13) -> 0 | G13: =SUMIF($K$5:$CV$5,G$5,$K13:$CV13) -> 0 | H13: =SUMIF($K$5:$CV$5,H$5,$K13:$CV13) -> 0 | I13: =SUMIF($K$5:$CV$5,I$5,$K13:$CV13) -> 0 | J13: =SUM(C13:I13) -> 0
B14: 合计 | C14: =SUMIF($K$3:$CU$3,C$3,$K14:$CU14) -> 0 | D14: =SUMIF($K$3:$CU$3,D$3,$K14:$CU14) -> 0 | E14: =SUMIF($K$3:$CU$3,E$3,$K14:$CU14) -> 0 | F14: =SUMIF($K$3:$CU$3,F$3,$K14:$CU14) -> 0 | G14: =SUMIF($K$3:$CU$3,G$3,$K14:$CU14) -> 0 | H14: =SUMIF($K$3:$CU$3,H$3,$K14:$CU14) -> 0 | I14: =SUMIF($K$3:$CU$3,I$3,$K14:$CU14) -> 0 | J14: =SUM(C14:I14) -> 0 | K14: =SUM(K12:K13) -> 0 | T14: =SUM(T12:T13) -> 0 | AC14: =SUM(AC12:AC13) -> 0 | AL14: =SUM(AL12:AL13) -> 0 | AU14: =SUM(AU12:AU13) -> 0 | BD14: =SUM(BD12:BD13) -> 0 | BM14: =SUM(BM12:BM13) -> 0 | BV14: =SUM(BV12:BV13) -> 0 | CE14: =SUM(CE12:CE13) -> 0 | CN14: =SUM(CN12:CN13) -> 0 | CU14: =SUM(CU12:CU13) -> 0
A15: 收款人
A16: 收款卡号
A17: 可分配利润（实收佣金-广告费） | J17: =J14-C4 -> 0
J52: 吴含雪
C53: 2号朱于森龚建成交通3182 | J53: 朱于森
C54: 3号梅雯慧张文俊支付宝 | J54: 梅雯慧
C55: 3号梅雯慧龚爱珍工商0765 | J55: 齐满艳
C56: 4号齐满艳龚爱珍农业1671 | J56: 陈正深
C57: 4号齐满艳张文俊农业0089 | J57: 齐青青
C58: 5号陈正深张文俊支付宝 | J58: 朱文欣
C59: 5号陈正深张文俊建设5707 | J59: 张耀红
C60: 6号齐青青龚建成中信6613 | J60: 胡雪茜
C61: 6号齐青青张文俊工商5542 | J61: 蓝晨馨
C62: 7号朱文欣龚建成交通3183
C63: 7号朱文欣龚建成建设数2576
C64: 8号张耀红张文俊广发8727
C65: 8号张耀红张文俊建设数2659
C66: 9号胡雪茜龚建成广发1786
C67: 9号胡雪茜龚建成工商3179
C68: 9号胡雪茜龚建成工商3306
C69: 10号蓝晨馨龚建成中信4298
C70: 10号蓝晨馨张文雅建行3055

Sheet 4月份
A1: 月份
A2: MCC | C2: 合计 | K2: 吴含雪 | T2: 朱于森 | AC2: 梅雯慧 | AL2: 齐满艳 | AU2: 陈正深 | BD2: 齐青青 | BM2: 朱文欣 | BV2: 张耀虹 | CE2: 胡雪茜 | CN2: 蓝晨馨
A3: 币种 | C3: 美金 | F3: 人民币 | I3: 在跑广告量 | K3: 美金 | L3: 美金 | M3: 美金 | N3: 美金 | O3: 美金 | P3: 美金 | Q3: 美金 | R3: 人民币 | S3: 在跑广告量 | T3: 美金 | U3: 美金 | V3: 美金 | W3: 美金 | X3: 美金 | Y3: 美金 | Z3: 美金 | AA3: 人民币 | AB3: 在跑广告量 | AC3: 美金 | AD3: 美金 | AE3: 美金 | AF3: 美金 | AG3: 美金 | AH3: 美金 | AI3: 美金 | AJ3: 人民币 | AK3: 在跑广告量 | AL3: 美金 | AM3: 美金 | AN3: 美金 | AO3: 美金 | AP3: 美金 | AQ3: 美金 | AR3: 美金 | AS3: 人民币 | AT3: 在跑广告量 | AU3: 美金 | AV3: 美金 | AW3: 美金 | AX3: 美金 | AY3: 美金 | AZ3: 美金 | BA3: 美金 | BB3: 人民币 | BC3: 在跑广告量 | BD3: 美金 | BE3: 美金 | BF3: 美金 | BG3: 美金 | BH3: 美金 | BI3: 美金 | BJ3: 美金 | BK3: 人民币 | BL3: 在跑广告量 | BM3: 美金 | BN3: 美金 | BO3: 美金 | BP3: 美金 | BQ3: 美金 | BR3: 美金 | BS3: 美金 | BT3: 人民币 | BU3: 在跑广告量 | BV3: 美金 | BW3: 美金 | BX3: 美金 | BY3: 美金 | BZ3: 美金 | CA3: 美金 | CB3: 美金 | CC3: 人民币 | CD3: 在跑广告量 | CE3: 美金 | CF3: 美金 | CG3: 美金 | CH3: 美金 | CI3: 美金 | CJ3: 美金 | CK3: 美金 | CL3: 人民币 | CM3: 在跑广告量 | CN3: 美金 | CO3: 美金 | CP3: 美金 | CQ3: 美金 | CR3: 美金 | CS3: 美金 | CT3: 美金 | CU3: 人民币 | CV3: 在跑广告量
A4: 广告费
A5: 广告联盟 | C5: RW | D5: LH | E5: CG | F5: LB | G5: PM | H5: CF | I5: BSH | J5: 合计 | K5: RW | L5: LH | M5: CG | N5: LB | O5: PM | P5: CF | Q5: BSH | T5: RW | U5: LH | V5: CG | W5: LB | X5: PM | Y5: CF | Z5: BSH | AC5: RW | AD5: LH | AE5: CG | AF5: LB | AG5: PM | AH5: CF | AI5: BSH | AL5: RW | AM5: LH | AN5: CG | AO5: LB | AP5: PM | AQ5: CF | AR5: BSH | AU5: RW | AV5: LH | AW5: CG | AX5: LB | AY5: PM | AZ5: CF | BA5: BSH | BD5: RW | BE5: LH | BF5: CG | BG5: LB | BH5: PM | BI5: CF | BJ5: BSH | BM5: RW | BN5: LH | BO5: CG | BP5: LB | BQ5: PM | BR5: CF | BS5: BSH | BV5: RW | BW5: LH | BX5: CG | BY5: LB | BZ5: PM | CA5: CF | CB5: BSH | CE5: RW | CF5: LH | CG5: CG | CH5: LB | CI5: PM | CJ5: CF | CK5: BSH | CN5: RW | CO5: LH | CP5: CG | CQ5: LB | CR5: PM | CS5: CF | CT5: BSH
A6: 账号名称
A7: 账面佣金（美金）
A8: 失效佣金（美金）
A9: 应收佣金（美金） | B9: 5号 | C9: =SUMIF($K$5:$CV$5,C$5,$K9:$CV9) -> 0 | D9: =SUMIF($K$5:$CV$5,D$5,$K9:$CV9) -> 0 | E9: =SUMIF($K$5:$CV$5,E$5,$K9:$CV9) -> 0 | F9: =SUMIF($K$5:$CV$5,F$5,$K9:$CV9) -> 0 | G9: =SUMIF($K$5:$CV$5,G$5,$K9:$CV9) -> 0 | H9: =SUMIF($K$5:$CV$5,H$5,$K9:$CV9) -> 0 | I9: =SUMIF($K$5:$CV$5,I$5,$K9:$CV9) -> 0 | J9: =SUM(C9:I9) -> 0
B10: 15号 | C10: =SUMIF($K$5:$CV$5,C$5,$K10:$CV10) -> 0 | D10: =SUMIF($K$5:$CV$5,D$5,$K10:$CV10) -> 0 | E10: =SUMIF($K$5:$CV$5,E$5,$K10:$CV10) -> 0 | F10: =SUMIF($K$5:$CV$5,F$5,$K10:$CV10) -> 0 | G10: =SUMIF($K$5:$CV$5,G$5,$K10:$CV10) -> 0 | H10: =SUMIF($K$5:$CV$5,H$5,$K10:$CV10) -> 0 | I10: =SUMIF($K$5:$CV$5,I$5,$K10:$CV10) -> 0 | J10: =SUM(C10:I10) -> 0
B11: 合计 | C11: =SUM(C9:C10) -> 0 | D11: =SUM(D9:D10) -> 0 | E11: =SUM(E9:E10) -> 0 | F11: =SUM(F9:F10) -> 0 | G11: =SUM(G9:G10) -> 0 | H11: =SUM(H9:H10) -> 0 | I11: =SUM(I9:I10) -> 0 | J11: =SUM(C11:I11) -> 0 | K11: =SUM(K9:K10) -> 0 | T11: =SUM(T9:T10) -> 0 | AC11: =SUM(AC9:AC10) -> 0 | AL11: =SUM(AL9:AL10) -> 0 | AU11: =SUM(AU9:AU10) -> 0 | BD11: =SUM(BD9:BD10) -> 0 | BM11: =SUM(BM9:BM10) -> 0 | BV11: =SUM(BV9:BV10) -> 0 | CE11: =SUM(CE9:CE10) -> 0 | CN11: =SUM(CN9:CN10) -> 0 | CU11: =SUM(CU9:CU10) -> 0
A12: 实收佣金（人民币） | B12: 10号 | C12: =SUMIF($K$5:$CV$5,C$5,$K12:$CV12) -> 0 | D12: =SUMIF($K$5:$CV$5,D$5,$K12:$CV12) -> 0 | E12: =SUMIF($K$5:$CV$5,E$5,$K12:$CV12) -> 0 | F12: =SUMIF($K$5:$CV$5,F$5,$K12:$CV12) -> 0 | G12: =SUMIF($K$5:$CV$5,G$5,$K12:$CV12) -> 0 | H12: =SUMIF($K$5:$CV$5,H$5,$K12:$CV12) -> 0 | I12: =SUMIF($K$5:$CV$5,I$5,$K12:$CV12) -> 0 | J12: =SUM(C12:I12) -> 0
B13: 20号 | C13: =SUMIF($K$5:$CV$5,C$5,$K13:$CV13) -> 0 | D13: =SUMIF($K$5:$CV$5,D$5,$K13:$CV13) -> 0 | E13: =SUMIF($K$5:$CV$5,E$5,$K13:$CV13) -> 0 | F13: =SUMIF($K$5:$CV$5,F$5,$K13:$CV13) -> 0 | G13: =SUMIF($K$5:$CV$5,G$5,$K13:$CV13) -> 0 | H13: =SUMIF($K$5:$CV$5,H$5,$K13:$CV13) -> 0 | I13: =SUMIF($K$5:$CV$5,I$5,$K13:$CV13) -> 0 | J13: =SUM(C13:I13) -> 0
B14: 合计 | C14: =SUMIF($K$3:$CU$3,C$3,$K14:$CU14) -> 0 | D14: =SUMIF($K$3:$CU$3,D$3,$K14:$CU14) -> 0 | E14: =SUMIF($K$3:$CU$3,E$3,$K14:$CU14) -> 0 | F14: =SUMIF($K$3:$CU$3,F$3,$K14:$CU14) -> 0 | G14: =SUMIF($K$3:$CU$3,G$3,$K14:$CU14) -> 0 | H14: =SUMIF($K$3:$CU$3,H$3,$K14:$CU14) -> 0 | I14: =SUMIF($K$3:$CU$3,I$3,$K14:$CU14) -> 0 | J14: =SUM(C14:I14) -> 0 | K14: =SUM(K12:K13) -> 0 | T14: =SUM(T12:T13) -> 0 | AC14: =SUM(AC12:AC13) -> 0 | AL14: =SUM(AL12:AL13) -> 0 | AU14: =SUM(AU12:AU13) -> 0 | BD14: =SUM(BD12:BD13) -> 0 | BM14: =SUM(BM12:BM13) -> 0 | BV14: =SUM(BV12:BV13) -> 0 | CE14: =SUM(CE12:CE13) -> 0 | CN14: =SUM(CN12:CN13) -> 0 | CU14: =SUM(CU12:CU13) -> 0
A15: 收款人
A16: 收款卡号
A17: 可分配利润（实收佣金-广告费） | J17: =J14-C4 -> 0
J52: 吴含雪
C53: 2号朱于森龚建成交通3182 | J53: 朱于森
C54: 3号梅雯慧张文俊支付宝 | J54: 梅雯慧
C55: 3号梅雯慧龚爱珍工商0765 | J55: 齐满艳
C56: 4号齐满艳龚爱珍农业1671 | J56: 陈正深
C57: 4号齐满艳张文俊农业0089 | J57: 齐青青
C58: 5号陈正深张文俊支付宝 | J58: 朱文欣
C59: 5号陈正深张文俊建设5707 | J59: 张耀红
C60: 6号齐青青龚建成中信6613 | J60: 胡雪茜
C61: 6号齐青青张文俊工商5542 | J61: 蓝晨馨
C62: 7号朱文欣龚建成交通3183
C63: 7号朱文欣龚建成建设数2576
C64: 8号张耀红张文俊广发8727
C65: 8号张耀红张文俊建设数2659
C66: 9号胡雪茜龚建成广发1786
C67: 9号胡雪茜龚建成工商3179
C68: 9号胡雪茜龚建成工商3306
C69: 10号蓝晨馨龚建成中信4298
C70: 10号蓝晨馨张文雅建行3055

Sheet 5月份
A1: 月份
A2: MCC | C2: 合计 | K2: 吴含雪 | T2: 朱于森 | AC2: 梅雯慧 | AL2: 齐满艳 | AU2: 陈正深 | BD2: 齐青青 | BM2: 朱文欣 | BV2: 张耀虹 | CE2: 胡雪茜 | CN2: 蓝晨馨
A3: 币种 | C3: 美金 | F3: 人民币 | I3: 在跑广告量 | K3: 美金 | L3: 美金 | M3: 美金 | N3: 美金 | O3: 美金 | P3: 美金 | Q3: 美金 | R3: 人民币 | S3: 在跑广告量 | T3: 美金 | U3: 美金 | V3: 美金 | W3: 美金 | X3: 美金 | Y3: 美金 | Z3: 美金 | AA3: 人民币 | AB3: 在跑广告量 | AC3: 美金 | AD3: 美金 | AE3: 美金 | AF3: 美金 | AG3: 美金 | AH3: 美金 | AI3: 美金 | AJ3: 人民币 | AK3: 在跑广告量 | AL3: 美金 | AM3: 美金 | AN3: 美金 | AO3: 美金 | AP3: 美金 | AQ3: 美金 | AR3: 美金 | AS3: 人民币 | AT3: 在跑广告量 | AU3: 美金 | AV3: 美金 | AW3: 美金 | AX3: 美金 | AY3: 美金 | AZ3: 美金 | BA3: 美金 | BB3: 人民币 | BC3: 在跑广告量 | BD3: 美金 | BE3: 美金 | BF3: 美金 | BG3: 美金 | BH3: 美金 | BI3: 美金 | BJ3: 美金 | BK3: 人民币 | BL3: 在跑广告量 | BM3: 美金 | BN3: 美金 | BO3: 美金 | BP3: 美金 | BQ3: 美金 | BR3: 美金 | BS3: 美金 | BT3: 人民币 | BU3: 在跑广告量 | BV3: 美金 | BW3: 美金 | BX3: 美金 | BY3: 美金 | BZ3: 美金 | CA3: 美金 | CB3: 美金 | CC3: 人民币 | CD3: 在跑广告量 | CE3: 美金 | CF3: 美金 | CG3: 美金 | CH3: 美金 | CI3: 美金 | CJ3: 美金 | CK3: 美金 | CL3: 人民币 | CM3: 在跑广告量 | CN3: 美金 | CO3: 美金 | CP3: 美金 | CQ3: 美金 | CR3: 美金 | CS3: 美金 | CT3: 美金 | CU3: 人民币 | CV3: 在跑广告量
A4: 广告费
A5: 广告联盟 | C5: RW | D5: LH | E5: CG | F5: LB | G5: PM | H5: CF | I5: BSH | J5: 合计 | K5: RW | L5: LH | M5: CG | N5: LB | O5: PM | P5: CF | Q5: BSH | T5: RW | U5: LH | V5: CG | W5: LB | X5: PM | Y5: CF | Z5: BSH | AC5: RW | AD5: LH | AE5: CG | AF5: LB | AG5: PM | AH5: CF | AI5: BSH | AL5: RW | AM5: LH | AN5: CG | AO5: LB | AP5: PM | AQ5: CF | AR5: BSH | AU5: RW | AV5: LH | AW5: CG | AX5: LB | AY5: PM | AZ5: CF | BA5: BSH | BD5: RW | BE5: LH | BF5: CG | BG5: LB | BH5: PM | BI5: CF | BJ5: BSH | BM5: RW | BN5: LH | BO5: CG | BP5: LB | BQ5: PM | BR5: CF | BS5: BSH | BV5: RW | BW5: LH | BX5: CG | BY5: LB | BZ5: PM | CA5: CF | CB5: BSH | CE5: RW | CF5: LH | CG5: CG | CH5: LB | CI5: PM | CJ5: CF | CK5: BSH | CN5: RW | CO5: LH | CP5: CG | CQ5: LB | CR5: PM | CS5: CF | CT5: BSH
A6: 账号名称
A7: 账面佣金（美金）
A8: 失效佣金（美金） | AU8: 0
A9: 应收佣金（美金） | B9: 5号 | C9: =SUMIF($K$5:$CV$5,C$5,$K9:$CV9) -> 0 | D9: =SUMIF($K$5:$CV$5,D$5,$K9:$CV9) -> 0 | E9: =SUMIF($K$5:$CV$5,E$5,$K9:$CV9) -> 0 | F9: =SUMIF($K$5:$CV$5,F$5,$K9:$CV9) -> 0 | G9: =SUMIF($K$5:$CV$5,G$5,$K9:$CV9) -> 0 | H9: =SUMIF($K$5:$CV$5,H$5,$K9:$CV9) -> 0 | I9: =SUMIF($K$5:$CV$5,I$5,$K9:$CV9) -> 0 | J9: =SUM(C9:I9) -> 0
B10: 15号 | C10: =SUMIF($K$5:$CV$5,C$5,$K10:$CV10) -> 0 | D10: =SUMIF($K$5:$CV$5,D$5,$K10:$CV10) -> 0 | E10: =SUMIF($K$5:$CV$5,E$5,$K10:$CV10) -> 0 | F10: =SUMIF($K$5:$CV$5,F$5,$K10:$CV10) -> 0 | G10: =SUMIF($K$5:$CV$5,G$5,$K10:$CV10) -> 0 | H10: =SUMIF($K$5:$CV$5,H$5,$K10:$CV10) -> 0 | I10: =SUMIF($K$5:$CV$5,I$5,$K10:$CV10) -> 0 | J10: =SUM(C10:I10) -> 0
B11: 合计 | C11: =SUM(C9:C10) -> 0 | D11: =SUM(D9:D10) -> 0 | E11: =SUM(E9:E10) -> 0 | F11: =SUM(F9:F10) -> 0 | G11: =SUM(G9:G10) -> 0 | H11: =SUM(H9:H10) -> 0 | I11: =SUM(I9:I10) -> 0 | J11: =SUM(C11:I11) -> 0 | K11: =SUM(K9:K10) -> 0 | T11: =SUM(T9:T10) -> 0 | AC11: =SUM(AC9:AC10) -> 0 | AL11: =SUM(AL9:AL10) -> 0 | AU11: =SUM(AU9:AU10) -> 0 | BD11: =SUM(BD9:BD10) -> 0 | BM11: =SUM(BM9:BM10) -> 0 | BV11: =SUM(BV9:BV10) -> 0 | CE11: =SUM(CE9:CE10) -> 0 | CN11: =SUM(CN9:CN10) -> 0 | CU11: =SUM(CU9:CU10) -> 0
A12: 实收佣金（人民币） | B12: 10号 | C12: =SUMIF($K$5:$CV$5,C$5,$K12:$CV12) -> 0 | D12: =SUMIF($K$5:$CV$5,D$5,$K12:$CV12) -> 0 | E12: =SUMIF($K$5:$CV$5,E$5,$K12:$CV12) -> 0 | F12: =SUMIF($K$5:$CV$5,F$5,$K12:$CV12) -> 0 | G12: =SUMIF($K$5:$CV$5,G$5,$K12:$CV12) -> 0 | H12: =SUMIF($K$5:$CV$5,H$5,$K12:$CV12) -> 0 | I12: =SUMIF($K$5:$CV$5,I$5,$K12:$CV12) -> 0 | J12: =SUM(C12:I12) -> 0
B13: 20号 | C13: =SUMIF($K$5:$CV$5,C$5,$K13:$CV13) -> 0 | D13: =SUMIF($K$5:$CV$5,D$5,$K13:$CV13) -> 0 | E13: =SUMIF($K$5:$CV$5,E$5,$K13:$CV13) -> 0 | F13: =SUMIF($K$5:$CV$5,F$5,$K13:$CV13) -> 0 | G13: =SUMIF($K$5:$CV$5,G$5,$K13:$CV13) -> 0 | H13: =SUMIF($K$5:$CV$5,H$5,$K13:$CV13) -> 0 | I13: =SUMIF($K$5:$CV$5,I$5,$K13:$CV13) -> 0 | J13: =SUM(C13:I13) -> 0
B14: 合计 | C14: =SUMIF($K$3:$CU$3,C$3,$K14:$CU14) -> 0 | D14: =SUMIF($K$3:$CU$3,D$3,$K14:$CU14) -> 0 | E14: =SUMIF($K$3:$CU$3,E$3,$K14:$CU14) -> 0 | F14: =SUMIF($K$3:$CU$3,F$3,$K14:$CU14) -> 0 | G14: =SUMIF($K$3:$CU$3,G$3,$K14:$CU14) -> 0 | H14: =SUMIF($K$3:$CU$3,H$3,$K14:$CU14) -> 0 | I14: =SUMIF($K$3:$CU$3,I$3,$K14:$CU14) -> 0 | J14: =SUM(C14:I14) -> 0 | K14: =SUM(K12:K13) -> 0 | T14: =SUM(T12:T13) -> 0 | AC14: =SUM(AC12:AC13) -> 0 | AL14: =SUM(AL12:AL13) -> 0 | AU14: =SUM(AU12:AU13) -> 0 | BD14: =SUM(BD12:BD13) -> 0 | BM14: =SUM(BM12:BM13) -> 0 | BV14: =SUM(BV12:BV13) -> 0 | CE14: =SUM(CE12:CE13) -> 0 | CN14: =SUM(CN12:CN13) -> 0 | CU14: =SUM(CU12:CU13) -> 0
A15: 收款人
A16: 收款卡号
A17: 可分配利润（实收佣金-广告费） | J17: =J14-C4 -> 0
J52: 吴含雪
C53: 2号朱于森龚建成交通3182 | J53: 朱于森
C54: 3号梅雯慧张文俊支付宝 | J54: 梅雯慧
C55: 3号梅雯慧龚爱珍工商0765 | J55: 齐满艳
C56: 4号齐满艳龚爱珍农业1671 | J56: 陈正深
C57: 4号齐满艳张文俊农业0089 | J57: 齐青青
C58: 5号陈正深张文俊支付宝 | J58: 朱文欣
C59: 5号陈正深张文俊建设5707 | J59: 张耀红
C60: 6号齐青青龚建成中信6613 | J60: 胡雪茜
C61: 6号齐青青张文俊工商5542 | J61: 蓝晨馨
C62: 7号朱文欣龚建成交通3183
C63: 7号朱文欣龚建成建设数2576
C64: 8号张耀红张文俊广发8727
C65: 8号张耀红张文俊建设数2659
C66: 9号胡雪茜龚建成广发1786
C67: 9号胡雪茜龚建成工商3179
C68: 9号胡雪茜龚建成工商3306
C69: 10号蓝晨馨龚建成中信4298
C70: 10号蓝晨馨张文雅建行3055

Sheet 6月份
A1: 月份
A2: MCC | C2: 合计 | K2: 吴含雪 | T2: 朱于森 | AC2: 梅雯慧 | AL2: 齐满艳 | AU2: 陈正深 | BD2: 齐青青 | BM2: 朱文欣 | BV2: 张耀虹 | CE2: 胡雪茜 | CN2: 蓝晨馨
A3: 币种 | C3: 美金 | F3: 人民币 | I3: 在跑广告量 | K3: 美金 | L3: 美金 | M3: 美金 | N3: 美金 | O3: 美金 | P3: 美金 | Q3: 美金 | R3: 人民币 | S3: 在跑广告量 | T3: 美金 | U3: 美金 | V3: 美金 | W3: 美金 | X3: 美金 | Y3: 美金 | Z3: 美金 | AA3: 人民币 | AB3: 在跑广告量 | AC3: 美金 | AD3: 美金 | AE3: 美金 | AF3: 美金 | AG3: 美金 | AH3: 美金 | AI3: 美金 | AJ3: 人民币 | AK3: 在跑广告量 | AL3: 美金 | AM3: 美金 | AN3: 美金 | AO3: 美金 | AP3: 美金 | AQ3: 美金 | AR3: 美金 | AS3: 人民币 | AT3: 在跑广告量 | AU3: 美金 | AV3: 美金 | AW3: 美金 | AX3: 美金 | AY3: 美金 | AZ3: 美金 | BA3: 美金 | BB3: 人民币 | BC3: 在跑广告量 | BD3: 美金 | BE3: 美金 | BF3: 美金 | BG3: 美金 | BH3: 美金 | BI3: 美金 | BJ3: 美金 | BK3: 人民币 | BL3: 在跑广告量 | BM3: 美金 | BN3: 美金 | BO3: 美金 | BP3: 美金 | BQ3: 美金 | BR3: 美金 | BS3: 美金 | BT3: 人民币 | BU3: 在跑广告量 | BV3: 美金 | BW3: 美金 | BX3: 美金 | BY3: 美金 | BZ3: 美金 | CA3: 美金 | CB3: 美金 | CC3: 人民币 | CD3: 在跑广告量 | CE3: 美金 | CF3: 美金 | CG3: 美金 | CH3: 美金 | CI3: 美金 | CJ3: 美金 | CK3: 美金 | CL3: 人民币 | CM3: 在跑广告量 | CN3: 美金 | CO3: 美金 | CP3: 美金 | CQ3: 美金 | CR3: 美金 | CS3: 美金 | CT3: 美金 | CU3: 人民币 | CV3: 在跑广告量
A4: 广告费
A5: 广告联盟 | C5: RW | D5: LH | E5: CG | F5: LB | G5: PM | H5: CF | I5: BSH | J5: 合计 | K5: RW | L5: LH | M5: CG | N5: LB | O5: PM | P5: CF | Q5: BSH | T5: RW | U5: LH | V5: CG | W5: LB | X5: PM | Y5: CF | Z5: BSH | AC5: RW | AD5: LH | AE5: CG | AF5: LB | AG5: PM | AH5: CF | AI5: BSH | AL5: RW | AM5: LH | AN5: CG | AO5: LB | AP5: PM | AQ5: CF | AR5: BSH | AU5: RW | AV5: LH | AW5: CG | AX5: LB | AY5: PM | AZ5: CF | BA5: BSH | BD5: RW | BE5: LH | BF5: CG | BG5: LB | BH5: PM | BI5: CF | BJ5: BSH | BM5: RW | BN5: LH | BO5: CG | BP5: LB | BQ5: PM | BR5: CF | BS5: BSH | BV5: RW | BW5: LH | BX5: CG | BY5: LB | BZ5: PM | CA5: CF | CB5: BSH | CE5: RW | CF5: LH | CG5: CG | CH5: LB | CI5: PM | CJ5: CF | CK5: BSH | CN5: RW | CO5: LH | CP5: CG | CQ5: LB | CR5: PM | CS5: CF | CT5: BSH
A6: 账号名称
A7: 账面佣金（美金）
A8: 失效佣金（美金）
A9: 应收佣金（美金） | B9: 5号 | C9: =SUMIF($K$5:$CV$5,C$5,$K9:$CV9) -> 0 | D9: =SUMIF($K$5:$CV$5,D$5,$K9:$CV9) -> 0 | E9: =SUMIF($K$5:$CV$5,E$5,$K9:$CV9) -> 0 | F9: =SUMIF($K$5:$CV$5,F$5,$K9:$CV9) -> 0 | G9: =SUMIF($K$5:$CV$5,G$5,$K9:$CV9) -> 0 | H9: =SUMIF($K$5:$CV$5,H$5,$K9:$CV9) -> 0 | I9: =SUMIF($K$5:$CV$5,I$5,$K9:$CV9) -> 0 | J9: =SUM(C9:I9) -> 0
B10: 15号 | C10: =SUMIF($K$5:$CV$5,C$5,$K10:$CV10) -> 0 | D10: =SUMIF($K$5:$CV$5,D$5,$K10:$CV10) -> 0 | E10: =SUMIF($K$5:$CV$5,E$5,$K10:$CV10) -> 0 | F10: =SUMIF($K$5:$CV$5,F$5,$K10:$CV10) -> 0 | G10: =SUMIF($K$5:$CV$5,G$5,$K10:$CV10) -> 0 | H10: =SUMIF($K$5:$CV$5,H$5,$K10:$CV10) -> 0 | I10: =SUMIF($K$5:$CV$5,I$5,$K10:$CV10) -> 0 | J10: =SUM(C10:I10) -> 0
B11: 合计 | C11: =SUM(C9:C10) -> 0 | D11: =SUM(D9:D10) -> 0 | E11: =SUM(E9:E10) -> 0 | F11: =SUM(F9:F10) -> 0 | G11: =SUM(G9:G10) -> 0 | H11: =SUM(H9:H10) -> 0 | I11: =SUM(I9:I10) -> 0 | J11: =SUM(C11:I11) -> 0 | K11: =SUM(K9:K10) -> 0 | T11: =SUM(T9:T10) -> 0 | AC11: =SUM(AC9:AC10) -> 0 | AL11: =SUM(AL9:AL10) -> 0 | AU11: =SUM(AU9:AU10) -> 0 | BD11: =SUM(BD9:BD10) -> 0 | BM11: =SUM(BM9:BM10) -> 0 | BV11: =SUM(BV9:BV10) -> 0 | CE11: =SUM(CE9:CE10) -> 0 | CN11: =SUM(CN9:CN10) -> 0 | CU11: =SUM(CU9:CU10) -> 0
A12: 实收佣金（人民币） | B12: 10号 | C12: =SUMIF($K$5:$CV$5,C$5,$K12:$CV12) -> 0 | D12: =SUMIF($K$5:$CV$5,D$5,$K12:$CV12) -> 0 | E12: =SUMIF($K$5:$CV$5,E$5,$K12:$CV12) -> 0 | F12: =SUMIF($K$5:$CV$5,F$5,$K12:$CV12) -> 0 | G12: =SUMIF($K$5:$CV$5,G$5,$K12:$CV12) -> 0 | H12: =SUMIF($K$5:$CV$5,H$5,$K12:$CV12) -> 0 | I12: =SUMIF($K$5:$CV$5,I$5,$K12:$CV12) -> 0 | J12: =SUM(C12:I12) -> 0
B13: 20号 | C13: =SUMIF($K$5:$CV$5,C$5,$K13:$CV13) -> 0 | D13: =SUMIF($K$5:$CV$5,D$5,$K13:$CV13) -> 0 | E13: =SUMIF($K$5:$CV$5,E$5,$K13:$CV13) -> 0 | F13: =SUMIF($K$5:$CV$5,F$5,$K13:$CV13) -> 0 | G13: =SUMIF($K$5:$CV$5,G$5,$K13:$CV13) -> 0 | H13: =SUMIF($K$5:$CV$5,H$5,$K13:$CV13) -> 0 | I13: =SUMIF($K$5:$CV$5,I$5,$K13:$CV13) -> 0 | J13: =SUM(C13:I13) -> 0
B14: 合计 | C14: =SUMIF($K$3:$CU$3,C$3,$K14:$CU14) -> 0 | D14: =SUMIF($K$3:$CU$3,D$3,$K14:$CU14) -> 0 | E14: =SUMIF($K$3:$CU$3,E$3,$K14:$CU14) -> 0 | F14: =SUMIF($K$3:$CU$3,F$3,$K14:$CU14) -> 0 | G14: =SUMIF($K$3:$CU$3,G$3,$K14:$CU14) -> 0 | H14: =SUMIF($K$3:$CU$3,H$3,$K14:$CU14) -> 0 | I14: =SUMIF($K$3:$CU$3,I$3,$K14:$CU14) -> 0 | J14: =SUM(C14:I14) -> 0 | K14: =SUM(K12:K13) -> 0 | T14: =SUM(T12:T13) -> 0 | AC14: =SUM(AC12:AC13) -> 0 | AL14: =SUM(AL12:AL13) -> 0 | AU14: =SUM(AU12:AU13) -> 0 | BD14: =SUM(BD12:BD13) -> 0 | BM14: =SUM(BM12:BM13) -> 0 | BV14: =SUM(BV12:BV13) -> 0 | CE14: =SUM(CE12:CE13) -> 0 | CN14: =SUM(CN12:CN13) -> 0 | CU14: =SUM(CU12:CU13) -> 0
A15: 收款人
A16: 收款卡号
A17: 可分配利润（实收佣金-广告费） | J17: =J14-C4 -> 0
J52: 吴含雪
C53: 2号朱于森龚建成交通3182 | J53: 朱于森
C54: 3号梅雯慧张文俊支付宝 | J54: 梅雯慧
C55: 3号梅雯慧龚爱珍工商0765 | J55: 齐满艳
C56: 4号齐满艳龚爱珍农业1671 | J56: 陈正深
C57: 4号齐满艳张文俊农业0089 | J57: 齐青青
C58: 5号陈正深张文俊支付宝 | J58: 朱文欣
C59: 5号陈正深张文俊建设5707 | J59: 张耀红
C60: 6号齐青青龚建成中信6613 | J60: 胡雪茜
C61: 6号齐青青张文俊工商5542 | J61: 蓝晨馨
C62: 7号朱文欣龚建成交通3183
C63: 7号朱文欣龚建成建设数2576
C64: 8号张耀红张文俊广发8727
C65: 8号张耀红张文俊建设数2659
C66: 9号胡雪茜龚建成广发1786
C67: 9号胡雪茜龚建成工商3179
C68: 9号胡雪茜龚建成工商3306
C69: 10号蓝晨馨龚建成中信4298
C70: 10号蓝晨馨张文雅建行3055

Sheet 7月份
A1: 月份
A2: MCC | C2: 合计 | K2: 吴含雪 | T2: 朱于森 | AC2: 梅雯慧 | AL2: 齐满艳 | AU2: 陈正深 | BD2: 齐青青 | BM2: 朱文欣 | BV2: 张耀虹 | CE2: 胡雪茜 | CN2: 蓝晨馨
A3: 币种 | C3: 美金 | F3: 人民币 | I3: 在跑广告量 | K3: 美金 | L3: 美金 | M3: 美金 | N3: 美金 | O3: 美金 | P3: 美金 | Q3: 美金 | R3: 人民币 | S3: 在跑广告量 | T3: 美金 | U3: 美金 | V3: 美金 | W3: 美金 | X3: 美金 | Y3: 美金 | Z3: 美金 | AA3: 人民币 | AB3: 在跑广告量 | AC3: 美金 | AD3: 美金 | AE3: 美金 | AF3: 美金 | AG3: 美金 | AH3: 美金 | AI3: 美金 | AJ3: 人民币 | AK3: 在跑广告量 | AL3: 美金 | AM3: 美金 | AN3: 美金 | AO3: 美金 | AP3: 美金 | AQ3: 美金 | AR3: 美金 | AS3: 人民币 | AT3: 在跑广告量 | AU3: 美金 | AV3: 美金 | AW3: 美金 | AX3: 美金 | AY3: 美金 | AZ3: 美金 | BA3: 美金 | BB3: 人民币 | BC3: 在跑广告量 | BD3: 美金 | BE3: 美金 | BF3: 美金 | BG3: 美金 | BH3: 美金 | BI3: 美金 | BJ3: 美金 | BK3: 人民币 | BL3: 在跑广告量 | BM3: 美金 | BN3: 美金 | BO3: 美金 | BP3: 美金 | BQ3: 美金 | BR3: 美金 | BS3: 美金 | BT3: 人民币 | BU3: 在跑广告量 | BV3: 美金 | BW3: 美金 | BX3: 美金 | BY3: 美金 | BZ3: 美金 | CA3: 美金 | CB3: 美金 | CC3: 人民币 | CD3: 在跑广告量 | CE3: 美金 | CF3: 美金 | CG3: 美金 | CH3: 美金 | CI3: 美金 | CJ3: 美金 | CK3: 美金 | CL3: 人民币 | CM3: 在跑广告量 | CN3: 美金 | CO3: 美金 | CP3: 美金 | CQ3: 美金 | CR3: 美金 | CS3: 美金 | CT3: 美金 | CU3: 人民币 | CV3: 在跑广告量
A4: 广告费
A5: 广告联盟 | C5: RW | D5: LH | E5: CG | F5: LB | G5: PM | H5: CF | I5: BSH | J5: 合计 | K5: RW | L5: LH | M5: CG | N5: LB | O5: PM | P5: CF | Q5: BSH | T5: RW | U5: LH | V5: CG | W5: LB | X5: PM | Y5: CF | Z5: BSH | AC5: RW | AD5: LH | AE5: CG | AF5: LB | AG5: PM | AH5: CF | AI5: BSH | AL5: RW | AM5: LH | AN5: CG | AO5: LB | AP5: PM | AQ5: CF | AR5: BSH | AU5: RW | AV5: LH | AW5: CG | AX5: LB | AY5: PM | AZ5: CF | BA5: BSH | BD5: RW | BE5: LH | BF5: CG | BG5: LB | BH5: PM | BI5: CF | BJ5: BSH | BM5: RW | BN5: LH | BO5: CG | BP5: LB | BQ5: PM | BR5: CF | BS5: BSH | BV5: RW | BW5: LH | BX5: CG | BY5: LB | BZ5: PM | CA5: CF | CB5: BSH | CE5: RW | CF5: LH | CG5: CG | CH5: LB | CI5: PM | CJ5: CF | CK5: BSH | CN5: RW | CO5: LH | CP5: CG | CQ5: LB | CR5: PM | CS5: CF | CT5: BSH
A6: 账号名称
A7: 账面佣金（美金）
A8: 失效佣金（美金）
A9: 应收佣金（美金） | B9: 5号 | C9: =SUMIF($K$5:$CV$5,C$5,$K9:$CV9) -> 0 | D9: =SUMIF($K$5:$CV$5,D$5,$K9:$CV9) -> 0 | E9: =SUMIF($K$5:$CV$5,E$5,$K9:$CV9) -> 0 | F9: =SUMIF($K$5:$CV$5,F$5,$K9:$CV9) -> 0 | G9: =SUMIF($K$5:$CV$5,G$5,$K9:$CV9) -> 0 | H9: =SUMIF($K$5:$CV$5,H$5,$K9:$CV9) -> 0 | I9: =SUMIF($K$5:$CV$5,I$5,$K9:$CV9) -> 0 | J9: =SUM(C9:I9) -> 0
B10: 15号 | C10: =SUMIF($K$5:$CV$5,C$5,$K10:$CV10) -> 0 | D10: =SUMIF($K$5:$CV$5,D$5,$K10:$CV10) -> 0 | E10: =SUMIF($K$5:$CV$5,E$5,$K10:$CV10) -> 0 | F10: =SUMIF($K$5:$CV$5,F$5,$K10:$CV10) -> 0 | G10: =SUMIF($K$5:$CV$5,G$5,$K10:$CV10) -> 0 | H10: =SUMIF($K$5:$CV$5,H$5,$K10:$CV10) -> 0 | I10: =SUMIF($K$5:$CV$5,I$5,$K10:$CV10) -> 0 | J10: =SUM(C10:I10) -> 0
B11: 合计 | C11: =SUM(C9:C10) -> 0 | D11: =SUM(D9:D10) -> 0 | E11: =SUM(E9:E10) -> 0 | F11: =SUM(F9:F10) -> 0 | G11: =SUM(G9:G10) -> 0 | H11: =SUM(H9:H10) -> 0 | I11: =SUM(I9:I10) -> 0 | J11: =SUM(C11:I11) -> 0 | K11: =SUM(K9:K10) -> 0 | T11: =SUM(T9:T10) -> 0 | AC11: =SUM(AC9:AC10) -> 0 | AL11: =SUM(AL9:AL10) -> 0 | AU11: =SUM(AU9:AU10) -> 0 | BD11: =SUM(BD9:BD10) -> 0 | BM11: =SUM(BM9:BM10) -> 0 | BV11: =SUM(BV9:BV10) -> 0 | CE11: =SUM(CE9:CE10) -> 0 | CN11: =SUM(CN9:CN10) -> 0 | CU11: =SUM(CU9:CU10) -> 0
A12: 实收佣金（人民币） | B12: 10号 | C12: =SUMIF($K$5:$CV$5,C$5,$K12:$CV12) -> 0 | D12: =SUMIF($K$5:$CV$5,D$5,$K12:$CV12) -> 0 | E12: =SUMIF($K$5:$CV$5,E$5,$K12:$CV12) -> 0 | F12: =SUMIF($K$5:$CV$5,F$5,$K12:$CV12) -> 0 | G12: =SUMIF($K$5:$CV$5,G$5,$K12:$CV12) -> 0 | H12: =SUMIF($K$5:$CV$5,H$5,$K12:$CV12) -> 0 | I12: =SUMIF($K$5:$CV$5,I$5,$K12:$CV12) -> 0 | J12: =SUM(C12:I12) -> 0
B13: 20号 | C13: =SUMIF($K$5:$CV$5,C$5,$K13:$CV13) -> 0 | D13: =SUMIF($K$5:$CV$5,D$5,$K13:$CV13) -> 0 | E13: =SUMIF($K$5:$CV$5,E$5,$K13:$CV13) -> 0 | F13: =SUMIF($K$5:$CV$5,F$5,$K13:$CV13) -> 0 | G13: =SUMIF($K$5:$CV$5,G$5,$K13:$CV13) -> 0 | H13: =SUMIF($K$5:$CV$5,H$5,$K13:$CV13) -> 0 | I13: =SUMIF($K$5:$CV$5,I$5,$K13:$CV13) -> 0 | J13: =SUM(C13:I13) -> 0
B14: 合计 | C14: =SUMIF($K$3:$CU$3,C$3,$K14:$CU14) -> 0 | D14: =SUMIF($K$3:$CU$3,D$3,$K14:$CU14) -> 0 | E14: =SUMIF($K$3:$CU$3,E$3,$K14:$CU14) -> 0 | F14: =SUMIF($K$3:$CU$3,F$3,$K14:$CU14) -> 0 | G14: =SUMIF($K$3:$CU$3,G$3,$K14:$CU14) -> 0 | H14: =SUMIF($K$3:$CU$3,H$3,$K14:$CU14) -> 0 | I14: =SUMIF($K$3:$CU$3,I$3,$K14:$CU14) -> 0 | J14: =SUM(C14:I14) -> 0 | K14: =SUM(K12:K13) -> 0 | T14: =SUM(T12:T13) -> 0 | AC14: =SUM(AC12:AC13) -> 0 | AL14: =SUM(AL12:AL13) -> 0 | AU14: =SUM(AU12:AU13) -> 0 | BD14: =SUM(BD12:BD13) -> 0 | BM14: =SUM(BM12:BM13) -> 0 | BV14: =SUM(BV12:BV13) -> 0 | CE14: =SUM(CE12:CE13) -> 0 | CN14: =SUM(CN12:CN13) -> 0 | CU14: =SUM(CU12:CU13) -> 0
A15: 收款人
A16: 收款卡号
A17: 可分配利润（实收佣金-广告费） | J17: =J14-C4 -> 0
J52: 吴含雪
C53: 2号朱于森龚建成交通3182 | J53: 朱于森
C54: 3号梅雯慧张文俊支付宝 | J54: 梅雯慧
C55: 3号梅雯慧龚爱珍工商0765 | J55: 齐满艳
C56: 4号齐满艳龚爱珍农业1671 | J56: 陈正深
C57: 4号齐满艳张文俊农业0089 | J57: 齐青青
C58: 5号陈正深张文俊支付宝 | J58: 朱文欣
C59: 5号陈正深张文俊建设5707 | J59: 张耀红
C60: 6号齐青青龚建成中信6613 | J60: 胡雪茜
C61: 6号齐青青张文俊工商5542 | J61: 蓝晨馨
C62: 7号朱文欣龚建成交通3183
C63: 7号朱文欣龚建成建设数2576
C64: 8号张耀红张文俊广发8727
C65: 8号张耀红张文俊建设数2659
C66: 9号胡雪茜龚建成广发1786
C67: 9号胡雪茜龚建成工商3179
C68: 9号胡雪茜龚建成工商3306
C69: 10号蓝晨馨龚建成中信4298
C70: 10号蓝晨馨张文雅建行3055

Sheet 8月份
A1: 月份
A2: MCC | C2: 合计 | K2: 吴含雪 | T2: 朱于森 | AC2: 梅雯慧 | AL2: 齐满艳 | AU2: 陈正深 | BD2: 齐青青 | BM2: 朱文欣 | BV2: 张耀虹 | CE2: 胡雪茜 | CN2: 蓝晨馨
A3: 币种 | C3: 美金 | F3: 人民币 | I3: 在跑广告量 | K3: 美金 | L3: 美金 | M3: 美金 | N3: 美金 | O3: 美金 | P3: 美金 | Q3: 美金 | R3: 人民币 | S3: 在跑广告量 | T3: 美金 | U3: 美金 | V3: 美金 | W3: 美金 | X3: 美金 | Y3: 美金 | Z3: 美金 | AA3: 人民币 | AB3: 在跑广告量 | AC3: 美金 | AD3: 美金 | AE3: 美金 | AF3: 美金 | AG3: 美金 | AH3: 美金 | AI3: 美金 | AJ3: 人民币 | AK3: 在跑广告量 | AL3: 美金 | AM3: 美金 | AN3: 美金 | AO3: 美金 | AP3: 美金 | AQ3: 美金 | AR3: 美金 | AS3: 人民币 | AT3: 在跑广告量 | AU3: 美金 | AV3: 美金 | AW3: 美金 | AX3: 美金 | AY3: 美金 | AZ3: 美金 | BA3: 美金 | BB3: 人民币 | BC3: 在跑广告量 | BD3: 美金 | BE3: 美金 | BF3: 美金 | BG3: 美金 | BH3: 美金 | BI3: 美金 | BJ3: 美金 | BK3: 人民币 | BL3: 在跑广告量 | BM3: 美金 | BN3: 美金 | BO3: 美金 | BP3: 美金 | BQ3: 美金 | BR3: 美金 | BS3: 美金 | BT3: 人民币 | BU3: 在跑广告量 | BV3: 美金 | BW3: 美金 | BX3: 美金 | BY3: 美金 | BZ3: 美金 | CA3: 美金 | CB3: 美金 | CC3: 人民币 | CD3: 在跑广告量 | CE3: 美金 | CF3: 美金 | CG3: 美金 | CH3: 美金 | CI3: 美金 | CJ3: 美金 | CK3: 美金 | CL3: 人民币 | CM3: 在跑广告量 | CN3: 美金 | CO3: 美金 | CP3: 美金 | CQ3: 美金 | CR3: 美金 | CS3: 美金 | CT3: 美金 | CU3: 人民币 | CV3: 在跑广告量
A4: 广告费
A5: 广告联盟 | C5: RW | D5: LH | E5: CG | F5: LB | G5: PM | H5: CF | I5: BSH | J5: 合计 | K5: RW | L5: LH | M5: CG | N5: LB | O5: PM | P5: CF | Q5: BSH | T5: RW | U5: LH | V5: CG | W5: LB | X5: PM | Y5: CF | Z5: BSH | AC5: RW | AD5: LH | AE5: CG | AF5: LB | AG5: PM | AH5: CF | AI5: BSH | AL5: RW | AM5: LH | AN5: CG | AO5: LB | AP5: PM | AQ5: CF | AR5: BSH | AU5: RW | AV5: LH | AW5: CG | AX5: LB | AY5: PM | AZ5: CF | BA5: BSH | BD5: RW | BE5: LH | BF5: CG | BG5: LB | BH5: PM | BI5: CF | BJ5: BSH | BM5: RW | BN5: LH | BO5: CG | BP5: LB | BQ5: PM | BR5: CF | BS5: BSH | BV5: RW | BW5: LH | BX5: CG | BY5: LB | BZ5: PM | CA5: CF | CB5: BSH | CE5: RW | CF5: LH | CG5: CG | CH5: LB | CI5: PM | CJ5: CF | CK5: BSH | CN5: RW | CO5: LH | CP5: CG | CQ5: LB | CR5: PM | CS5: CF | CT5: BSH
A6: 账号名称
A7: 账面佣金（美金）
A8: 失效佣金（美金） | AU8: 0
A9: 应收佣金（美金） | B9: 5号 | C9: =SUMIF($K$5:$CV$5,C$5,$K9:$CV9) -> 0 | D9: =SUMIF($K$5:$CV$5,D$5,$K9:$CV9) -> 0 | E9: =SUMIF($K$5:$CV$5,E$5,$K9:$CV9) -> 0 | F9: =SUMIF($K$5:$CV$5,F$5,$K9:$CV9) -> 0 | G9: =SUMIF($K$5:$CV$5,G$5,$K9:$CV9) -> 0 | H9: =SUMIF($K$5:$CV$5,H$5,$K9:$CV9) -> 0 | I9: =SUMIF($K$5:$CV$5,I$5,$K9:$CV9) -> 0 | J9: =SUM(C9:I9) -> 0
B10: 15号 | C10: =SUMIF($K$5:$CV$5,C$5,$K10:$CV10) -> 0 | D10: =SUMIF($K$5:$CV$5,D$5,$K10:$CV10) -> 0 | E10: =SUMIF($K$5:$CV$5,E$5,$K10:$CV10) -> 0 | F10: =SUMIF($K$5:$CV$5,F$5,$K10:$CV10) -> 0 | G10: =SUMIF($K$5:$CV$5,G$5,$K10:$CV10) -> 0 | H10: =SUMIF($K$5:$CV$5,H$5,$K10:$CV10) -> 0 | I10: =SUMIF($K$5:$CV$5,I$5,$K10:$CV10) -> 0 | J10: =SUM(C10:I10) -> 0
B11: 合计 | C11: =SUM(C9:C10) -> 0 | D11: =SUM(D9:D10) -> 0 | E11: =SUM(E9:E10) -> 0 | F11: =SUM(F9:F10) -> 0 | G11: =SUM(G9:G10) -> 0 | H11: =SUM(H9:H10) -> 0 | I11: =SUM(I9:I10) -> 0 | J11: =SUM(C11:I11) -> 0 | K11: =SUM(K9:K10) -> 0 | T11: =SUM(T9:T10) -> 0 | AC11: =SUM(AC9:AC10) -> 0 | AL11: =SUM(AL9:AL10) -> 0 | AU11: =SUM(AU9:AU10) -> 0 | BD11: =SUM(BD9:BD10) -> 0 | BM11: =SUM(BM9:BM10) -> 0 | BV11: =SUM(BV9:BV10) -> 0 | CE11: =SUM(CE9:CE10) -> 0 | CN11: =SUM(CN9:CN10) -> 0 | CU11: =SUM(CU9:CU10) -> 0
A12: 实收佣金（人民币） | B12: 10号 | C12: =SUMIF($K$5:$CV$5,C$5,$K12:$CV12) -> 0 | D12: =SUMIF($K$5:$CV$5,D$5,$K12:$CV12) -> 0 | E12: =SUMIF($K$5:$CV$5,E$5,$K12:$CV12) -> 0 | F12: =SUMIF($K$5:$CV$5,F$5,$K12:$CV12) -> 0 | G12: =SUMIF($K$5:$CV$5,G$5,$K12:$CV12) -> 0 | H12: =SUMIF($K$5:$CV$5,H$5,$K12:$CV12) -> 0 | I12: =SUMIF($K$5:$CV$5,I$5,$K12:$CV12) -> 0 | J12: =SUM(C12:I12) -> 0
B13: 20号 | C13: =SUMIF($K$5:$CV$5,C$5,$K13:$CV13) -> 0 | D13: =SUMIF($K$5:$CV$5,D$5,$K13:$CV13) -> 0 | E13: =SUMIF($K$5:$CV$5,E$5,$K13:$CV13) -> 0 | F13: =SUMIF($K$5:$CV$5,F$5,$K13:$CV13) -> 0 | G13: =SUMIF($K$5:$CV$5,G$5,$K13:$CV13) -> 0 | H13: =SUMIF($K$5:$CV$5,H$5,$K13:$CV13) -> 0 | I13: =SUMIF($K$5:$CV$5,I$5,$K13:$CV13) -> 0 | J13: =SUM(C13:I13) -> 0
